Workbook

Sheet Manufacturing results
B1: Cost | C1: Unit | D1: Cost | E1: Unit | F1: Mass | G1: Unit | P1: Per stack
A2: Total costs | B2: =SUM(B4:B9) -> 0.11569801 | C2: €/cm^2 | D2: =SUM(D4:D9) -> 9.2558406 | E2: €/SRU | F2: =SUM(F4:F6) -> 183.35353 | G2: g/SRU | P2: =SUM(P4:P9) -> 555.35044
A4: Cell | B4: =SUM(Cell!L3:L1048576)/'Cross-layer'!B24 -> 0.0071937234 | C4: €/cm^2 | D4: =SUM(Cell!L3:L1048576) -> 0.57549787 | E4: €/SRU | F4: =SUM(Cell!M3:M1048576) -> 8.83024 | G4: g/SRU | P4: =D4*'Cross-layer'!$B$3 -> 34.529872
A5: Frame | B5: =SUM(Frame!M3:M1048576)/'Cross-layer'!B24 -> 0.04370141 | C5: €/cm^2 | D5: =SUM(Frame!M3:M1048576) -> 3.4961128 | E5: €/SRU | F5: =SUM(Frame!N3:N1048576) -> 167.59579 | G5: g/SRU | P5: =D5*'Cross-layer'!$B$3 -> 209.76677
A6: Miscellaneous | B6: =SUM(Misc!L3:L1048576)/'Cross-layer'!B24 -> 0.012416736 | C6: €/cm^2 | D6: =SUM(Misc!L3:L1048576) -> 0.99333889 | E6: €/SRU | F6: =SUM(Misc!M3:M1048576) -> 6.9274938 | G6: g/SRU | P6: =D6*'Cross-layer'!$B$3 -> 59.600333
A7: Machining | B7: =D7/'Cross-layer'!$B$24 -> 0.027498191 | C7: €/cm^2 | D7: =SUM('Manufacturing calc'!U:U) -> 2.1998553 | E7: €/SRU | P7: =D7*'Cross-layer'!$B$3 -> 131.99132
A8: Labour | B8: =D8/'Cross-layer'!$B$24 -> 0.01731351 | C8: €/cm^2 | D8: =SUM('Manufacturing calc'!V:V) -> 1.3850808 | E8: €/SRU | P8: =D8*'Cross-layer'!$B$3 -> 83.104848
A9: Energy | B9: =D9/'Cross-layer'!$B$24 -> 0.0075744373 | C9: €/cm^2 | D9: =SUM('Manufacturing calc'!W:W) -> 0.60595499 | E9: €/SRU | P9: =D9*'Cross-layer'!$B$3 -> 36.357299
A12: Further breakdown: | B12: €/cm^2 | C12: €/SRU | E12: =0.004867+0.0178170525499999 -> 0.022684053
A13: Cell | B13: =SUM(B14:B19) -> 0.0071937234 | C13: =SUM(C14:C19) -> 0.57549787
A14: Oxygen electrode | B14: =Cell!L3/'Cross-layer'!$B$24 -> 0.00077409574 | C14: =B14*'Cross-layer'!$B$24 -> 0.06192766
A15: Contact layer | B15: =Cell!L4/'Cross-layer'!$B$24 -> 0.00077409574 | C15: =B15*'Cross-layer'!$B$24 -> 0.06192766
A16: CGO Layer | B16: =Cell!L5/'Cross-layer'!$B$24 -> 0.0019715745 | C16: =B16*'Cross-layer'!$B$24 -> 0.15772596
A17: Electrolyte | B17: =Cell!L6/'Cross-layer'!$B$24 -> 0.0019905319 | C17: =B17*'Cross-layer'!$B$24 -> 0.15924255
A18: Ni-YSZ Active | B18: =(Cell!L7+Cell!L8)/'Cross-layer'!$B$24 -> 0.001538734 | C18: =B18*'Cross-layer'!$B$24 -> 0.12309872
A19: Ni-YSZ Support | B19: =(Cell!L9+Cell!L10)/'Cross-layer'!$B$24 -> 0.00014469149 | C19: =B19*'Cross-layer'!$B$24 -> 0.011575319
A20: Frame | B20: =SUM(B21:B24) -> 0.04370141 | C20: =SUM(C21:C24) -> 3.4961128
A21: Interconnects | B21: =(Frame!M3+Frame!M4)/'Cross-layer'!B24 -> 0.0093817277 | C21: =B21*'Cross-layer'!$B$24 -> 0.75053821
A22: Spacers | B22: =(Frame!M6+Frame!M7+Frame!M8)/'Cross-layer'!B24 -> 0.028702489 | C22: =B22*'Cross-layer'!$B$24 -> 2.2961991
A23: Current collectors | B23: =Frame!M5/'Cross-layer'!B24 -> 0.00060184213 | C23: =B23*'Cross-layer'!$B$24 -> 0.048147371
A24: Compression plates | B24: =Frame!M9/'Cross-layer'!B24 -> 0.0050153511 | C24: =B24*'Cross-layer'!$B$24 -> 0.40122809
A25: Misc | B25: =SUM(B26:B28) -> 0.012416736 | C25: =SUM(C26:C28) -> 0.99333889
A26: Glass sealant | B26: =Misc!L3/'Cross-layer'!$B$24 -> 0.0020726396 | C26: =Misc!L3 -> 0.16581117
A27: Protection coating | B27: =Misc!L4/'Cross-layer'!$B$24 -> 0.0076440965 | C27: =Misc!L4 -> 0.61152772
A28: Ni-Mesh layer | B28: =Misc!L5/'Cross-layer'!$B$24 -> 0.0027 | C28: =Misc!L5 -> 0.216
A29: Manufacturing and labour | B29: =SUM(B30:B34) -> 0.052386139 | C29: =SUM(C30:C34) -> 4.1908911
A30: =A40 -> Interconnects and frames | B30: =C30/'Cross-layer'!$B$24 -> 0.012304072 | C30: =SUM(B40:D40) -> 0.98432574
A31: =A41 -> Dies | B31: =C31/'Cross-layer'!$B$24 -> 0.0044756466 | C31: =SUM(B41:D41) -> 0.35805173
A32: =A42 -> Cells and glass sealants | B32: =C32/'Cross-layer'!$B$24 -> 0.016645713 | C32: =SUM(B42:D42) -> 1.3316571
A33: =A43 -> Pre-assembly | B33: =C33/'Cross-layer'!$B$24 -> 0.0084109442 | C33: =SUM(B43:D43) -> 0.67287553
A34: =A44 -> Final assembly | B34: =C34/'Cross-layer'!$B$24 -> 0.010549763 | C34: =SUM(B44:D44) -> 0.84398104
A39: Manufacturing breakdown | B39: Machines | C39: Labour | D39: Energy
A40: ='Manufacturing calc'!B12 -> Interconnects and frames | B40: =SUMIF('Manufacturing calc'!$B:$B,$A40,'Manufacturing calc'!U:U) -> 0.69278915 | C40: =SUMIF('Manufacturing calc'!$B:$B,$A40,'Manufacturing calc'!V:V) -> 0.17347764 | D40: =SUMIF('Manufacturing calc'!$B:$B,$A40,'Manufacturing calc'!W:W) -> 0.11805895
A41: Dies | B41: =SUMIF('Manufacturing calc'!$B:$B,$A41,'Manufacturing calc'!U:U) -> 0.35805173 | C41: =SUMIF('Manufacturing calc'!$B:$B,$A41,'Manufacturing calc'!V:V) -> 0 | D41: =SUMIF('Manufacturing calc'!$B:$B,$A41,'Manufacturing calc'!W:W) -> 0
A42: Cells and glass sealants | B42: =SUMIF('Manufacturing calc'!$B:$B,$A42,'Manufacturing calc'!U:U) -> 0.56910462 | C42: =SUMIF('Manufacturing calc'!$B:$B,$A42,'Manufacturing calc'!V:V) -> 0.56701944 | D42: =SUMIF('Manufacturing calc'!$B:$B,$A42,'Manufacturing calc'!W:W) -> 0.19553299
A43: Pre-assembly | B43: =SUMIF('Manufacturing calc'!$B:$B,$A43,'Manufacturing calc'!U:U) -> 0.32395316 | C43: =SUMIF('Manufacturing calc'!$B:$B,$A43,'Manufacturing calc'!V:V) -> 0.30057488 | D43: =SUMIF('Manufacturing calc'!$B:$B,$A43,'Manufacturing calc'!W:W) -> 0.048347496
A44: Final assembly | B44: =SUMIF('Manufacturing calc'!$B:$B,$A44,'Manufacturing calc'!U:U) -> 0.25595666 | C44: =SUMIF('Manufacturing calc'!$B:$B,$A44,'Manufacturing calc'!V:V) -> 0.34400884 | D44: =SUMIF('Manufacturing calc'!$B:$B,$A44,'Manufacturing calc'!W:W) -> 0.24401555
A47: Power input per stack | B47: =Performance!J8 -> 4.9448781 | C47: kWin/stack
A48: Power input per SRU | B48: =B47/'Cross-layer'!B3 -> 0.082414634 | C48: kWin/SRU
A50: Total cost per kWin | B50: =D2/$B$48 -> 112.30822 | C50: €/kW
...

Sheet Performance
A1: Input variable | B1: Value | C1: Unit | D1: Note | E1: Other parameters | F1: Value | G1: Unit | H1: Note | I1: Calculated values: | J1: Value | K1: Unit | L1: Note
A2: Operational parameters: | E2: Faraday constant | F2: 96485 | G2: [C/mol] | I2: Electrical system:
A3: Cell current density | B3: -0.8 | C3: [A/cm^2] | E3: Ideal gas constant | F3: 8.3145 | G3: J/(mol*K) | I3: Hydrogen flow per stack | J3: =-B3*F10*F11/(F4*F2) -> 0.019899466 | K3: [mol/s]
A4: Cell voltage | B4: =F17 -> 1.2877287 | C4: [V] | E4: Reaction electrons | F4: 2 | G4: [-] | I4: Mass flow | J4: =2.016*J3*3.6 -> 0.14442237 | K4: [kg/h]
A5: Temperature | B5: 850 | C5: [degC] | D5: round to closest 25 | E5: Current efficiency | F5: 1 | I5: Volume flow | J5: =J3*22.4 -> 0.44574804 | K5: [L/s]
A6: Pressure | B6: 5 | C6: bar | E6: Molar mass of steam | F6: =2.016+15.999 -> 18.015 | G6: g/mol | I6: Cell voltage efficiency | J6: =F17/B4 -> 1 | K6: [%]
A7: Steam utilization rate | B7: 0.8 | E7: LHV of H2 | F7: 33.333 | G7: [kWh/kg] | I7: Cell energy demand per kgH2 | J7: =F7/J10 -> 34.239005 | K7: kWh/kgH2
A8: Degradation rate | B8: 0.0077 | C8: /1000h | E8: USD -> EUR conversion | F8: 0.8512 | G8: USD/EUR | I8: Electrical input power | J8: =-B3*F10*F11*B4/1000 -> 4.9448781 | K8: [kWin/stack]
A9: Degradation at EOL | B9: 0.15 | I9: Power out | J9: =J4*F7 -> 4.8140307 | K9: [kWout/stack]
E10: Cell area | F10: ='Cross-layer'!B24 -> 80 | I10: Electrical efficiency | J10: =J9/J8 -> 0.97353882
E11: Cells per stack | F11: ='Cross-layer'!B3 -> 60
I12: Stack calculations:
E13: Operation temp [K] | F13: =B5+273.15 -> 1123.15 | G13: [K] | I13: kWh in per kgH2 | J13: =J7 -> 34.239005 | K13: [kWh/kg]
E14: Gibbs Free energy | F14: =INDEX(Tabel3[#Data],MATCH($F$13,Tabel3[T (K)]),4) -> -185.912 | G14: kJ/mol
E15: Enthalpy | F15: =INDEX(Tabel3[#Data],MATCH($F$13,Tabel3[T (K)]),2) -> -248.493 | G15: kJ/mol | I15: Total stack CAPEX | J15: ='Manufacturing results'!D2*F11 -> 555.35044 | K15: [€/stack]
E16: Reversible cell voltage | F16: =-F14*10^3/($F$4*$F$2) -> 0.96342437 | G16: V | I16: Stack CAPEX per input kW | J16: =J15/J8 -> 112.30822 | K16: [€/kW]
E17: Thermoneutral voltage | F17: =-F15*10^3/($F$4*$F$2) -> 1.2877287 | G17: V | I17: Consumed steam molar flow | J17: =J3 -> 0.019899466 | K17: [mol/s/stack]
I18: Steam mass flow | J18: =J17*F6*3.6 -> 1.29056 | K18: [kg/h/stack]
I19: Total system lifetime | J19: =(B9*100)/(B8*100)*1000 -> 19480.519 | K19: h

Sheet Cross-layer
A1: Key Values | B1: Input value | C1: Unit | D1: Explanation:
A2: Cells per SRU | B2: 1
A3: SRU per stack | B3: 60
A4: Length | B4: 10 | C4: cm
A5: Width | B5: 8 | C5: cm
A6: Small->Big cell | B6: 1 | C6: cm | D6: Length & width difference between smaller cell layers and larger cell layers
A7: Big cell->Frame | B7: 1.2 | C7: cm | D7: Length & width difference between cell and frame components
A8: Framing
A9: IC Thickness | B9: 300 | C9: µm
A10: Distance between IC | B10: 600 | C10: µm | D10: Assumed equal to spacer thickness
A11: Compression Thickness | B11: 5000 | C11: µm
A12: Spacer steel fraction | B12: =IF(B18="Without",1,Calculations!B43) -> 0.17616053 | D12: How much of the spacer is actual material (rest is cut out)?
A13: Compr/IC/collector steel fraction | B13: =IF(B18="Without",1,Calculations!B35) -> 0.97172466 | D13: How much of the IC/collector/compression plates is actual material?
A14: Scrap cost return (IC) | B14: 0.08 | D14: How much of the original cost is returned when reselling cut out steel?
A15: Scrap cost return (other) | B15: 0.28
A16: Decision variables:
A17: Steel material | B17: Crofer22APU
A18: With/Without reuse of cutouts | B18: With | D18: Either "With" or "Without" - Do we cut out and resell steel components?
A19: Cell discard rate | B19: 0.06 | D19: This is to reflect that not all cells are made perfectly, and some will have to be discarded due to imperfections
A21: Total footprint
A22: Length | B22: =B4+B6+B7 -> 12.2
A23: Width | B23: =B5+B6+B7 -> 10.2
A24: Small cell area | B24: =B4*B5 -> 80
A25: Big cell area | B25: =(B4+B6)*(B5+B6) -> 99
A26: Frame area | B26: =(B4+B6+B7)*(B5+B6+B7) -> 124.44
A27: Stacks per batch | B27: =181/B3 -> 3.0166667

Sheet Manufacturing inputs
A1: Production volume | B1: 5000 | C1: batches | F1: Table for max cycle time | G1: Shifts/day | H1: Hours/shift | I1: Hours/year | J1: Takt time
A2: Machine cost factor (CAPEX) | B2: =0.2/B1 -> 4e-05 | F2: Takt time, 1 shift (7.5 hrs) | G2: 1 | H2: 7.5 | I2: =$B$12*Max_cycle_table[[#This Row],[Shifts/day]]*Max_cycle_table[[#This Row],[Hours/shift]]*$B$11 -> 1434.375 | J2: =ROUND(I2*60^2/$B$14,1) -> 5.7
A3: Stacks per batch | B3: ='Cross-layer'!B27 -> 3.0166667 | F3: Takt time, 3 shift (7.5 hrs) | G3: 3 | H3: 7.5 | I3: =$B$12*Max_cycle_table[[#This Row],[Shifts/day]]*Max_cycle_table[[#This Row],[Hours/shift]]*$B$11 -> 4303.125 | J3: =ROUND(I3*60^2/$B$14,1) -> 17.1
A4: SRU per stack | B4: ='Cross-layer'!B3 -> 60 | F4: Takt time, 3 shift (8 hrs) | G4: 3 | H4: 8 | I4: =$B$12*Max_cycle_table[[#This Row],[Shifts/day]]*Max_cycle_table[[#This Row],[Hours/shift]]*$B$11 -> 4590 | J4: =ROUND(I4*60^2/$B$14,1) -> 18.3
A5: Layers per batch | B5: =B3*B4 -> 181 | F5: End plates | G5: 1 | H5: 7.5 | I5: =$B$12*Max_cycle_table[[#This Row],[Shifts/day]]*Max_cycle_table[[#This Row],[Hours/shift]]*$B$11 -> 1434.375 | J5: =ROUND(I5*60^2/(B3*B1),1) -> 342.3
A6: Power price | B6: 0.17 | C6: €/kWh
A7: Power cost per batch | B7: =B6*B5 -> 30.77 | C7: €/kWh
A8: -II- in kJ | B8: =B7/3600 -> 0.0085472222 | C8: €/kJ
A9: Annual salary, per labourer | B9: 86480 | C9: €/year
A11: Availability factor | B11: 0.85 | C11: [%]
A12: Work days per year | B12: 225 | C12: days/year
A14: Total SRU produced / year | B14: =B1*B5 -> 905000 | C14: SRU/year
A16: Overhead share (installment CAPEX) | B16: 0.3
A18: Scaling factors | B18: Value
A19: Big cell area | B19: ='Cross-layer'!B25*B27 -> 0.64705882
A20: Length | B20: =B29*'Cross-layer'!B4 -> 0.625
A21: Frame | B21: =B28*'Cross-layer'!B26 -> 0.50096618
A22: Per piece | B22: =B26*B5 -> 0.99889625
A24: Assumed 30.000 pieces before replacement
A26: Scaler, per piece | B26: =1/B44 -> 0.0055187638
A27: Scaler, big cell: | B27: =1/B40 -> 0.0065359477
A28: Scaler, frame: | B28: =1/B41 -> 0.0040257649
A29: Scaler, length: | B29: =1/B36 -> 0.0625
A31: For scaling factors:
A33: Harboe design parameters:
A34: Total length | B34: 18 | C34: cm
A35: Total width | B35: 13.8 | C35: cm
A36: Cell length | B36: 16 | C36: cm
A37: Cell width | B37: 8 | C37: cm
A38: SRU's per stack | B38: 60
A39: Small active area | B39: =B36*B37 -> 128 | C39: cm^2
A40: Big active area | B40: =(B36+1)*(B37+1) -> 153
A41: Frame area | B41: =B34*B35 -> 248.4 | C41: cm^2
A42: cell_ratio: | B42: =B40/B39 -> 1.1953125
A43: frame_ratio: | B43: =1.2 -> 1.2
A44: Layers per batch | B44: =B38*3.02 -> 181.2

Sheet Cell
C1: [€/kg] | D1: [µm] | E1: [%] | H1: [g/cm^3] | I1: [kg/m^2] | J1: [€/m^2] | K1: [cm^2] | L1: [€] | M1: [g] | O1: Assumptions:
A2: Layer | B2: Material | C2: Mat. Price | D2: Thickness | E2: Porosity | F2: Fraction in layer | G2: Volume% | H2: Mat. Density | I2: Mass | J2: Cost per area | K2: Area | L2: Cost per unit | M2: Mass per unit | O2: Cost of LSC = LSCF = LSFNT
A3: Oxygen electrode | B3: LSC | C3: =_xlfn.XLOOKUP(B3,Tabel2[Material],Tabel2[Cost],"Not found") -> 55 | D3: 30 | E3: 0.3 | F3: 1 | G3: =F3*(1-E3) -> 0.7 | H3: =_xlfn.XLOOKUP(B3,Tabel2[Material],Tabel2[Density],"Not found") -> 6.3 | I3: =H3*G3*D3/1000 -> 0.1323 | J3: =I3*C3 -> 7.2765 | K3: ='Cross-layer'!$B$24 -> 80 | L3: =K3/100/100*J3/(1-'Cross-layer'!$B$19) -> 0.06192766 | M3: =K3/100/100*I3*1000 -> 1.0584 | O3: Cost of Ni/CGO = CGO
A4: Contact layer | B4: LSC | C4: =_xlfn.XLOOKUP(B4,Tabel2[Material],Tabel2[Cost],"Not found") -> 55 | D4: 30 | E4: 0.3 | F4: 1 | G4: =F4*(1-E4) -> 0.7 | H4: =_xlfn.XLOOKUP(B4,Tabel2[Material],Tabel2[Density],"Not found") -> 6.3 | I4: =H4*G4*D4/1000 -> 0.1323 | J4: =I4*C4 -> 7.2765 | K4: ='Cross-layer'!$B$24 -> 80 | L4: =K4/100/100*J4/(1-'Cross-layer'!$B$19) -> 0.06192766 | M4: =K4/100/100*I4*1000 -> 1.0584 | O4: Ni/CGO cost/density is negligible
A5: CGO Layer | B5: CGO | C5: =_xlfn.XLOOKUP(B5,Tabel2[Material],Tabel2[Cost],"Not found") -> 260 | D5: 8 | E5: 0 | F5: 1 | G5: =F5*(1-E5) -> 1 | H5: =_xlfn.XLOOKUP(B5,Tabel2[Material],Tabel2[Density],"Not found") -> 7.2 | I5: =H5*G5*D5/1000 -> 0.0576 | J5: =I5*C5 -> 14.976 | K5: ='Cross-layer'!$B$25 -> 99 | L5: =K5/100/100*J5/(1-'Cross-layer'!$B$19) -> 0.15772596 | M5: =K5/100/100*I5*1000 -> 0.57024
A6: Electrolyte | B6: 8YSZ | C6: =_xlfn.XLOOKUP(B6,Tabel2[Material],Tabel2[Cost],"Not found") -> 30 | D6: 80 | E6: 0 | F6: 1 | G6: =F6*(1-E6) -> 1 | H6: =_xlfn.XLOOKUP(B6,Tabel2[Material],Tabel2[Density],"Not found") -> 6.3 | I6: =H6*G6*D6/1000 -> 0.504 | J6: =I6*C6 -> 15.12 | K6: ='Cross-layer'!$B$25 -> 99 | L6: =K6/100/100*J6/(1-'Cross-layer'!$B$19) -> 0.15924255 | M6: =K6/100/100*I6*1000 -> 4.9896 | O6: Template values based on the below design:
A7: FE active | B7: CGO | C7: =_xlfn.XLOOKUP(B7,Tabel2[Material],Tabel2[Cost],"Not found") -> 260 | D7: 20 | E7: 0.3 | F7: 0.5 | G7: =F7*(1-E7) -> 0.35 | H7: =_xlfn.XLOOKUP(B7,Tabel2[Material],Tabel2[Density],"Not found") -> 7.2 | I7: =H7*G7*D7/1000 -> 0.0504 | J7: =I7*C7 -> 13.104 | K7: ='Cross-layer'!$B$24 -> 80 | L7: =K7/100/100*J7/(1-'Cross-layer'!$B$19) -> 0.1115234 | M7: =K7/100/100*I7*1000 -> 0.4032
B8: NiO | C8: =_xlfn.XLOOKUP(B8,Tabel2[Material],Tabel2[Cost],"Not found") -> 29 | D8: 20 | E8: 0.3 | F8: 0.5 | G8: =F8*(1-E8) -> 0.35 | H8: =_xlfn.XLOOKUP(B8,Tabel2[Material],Tabel2[Density],"Not found") -> 6.7 | I8: =H8*G8*D8/1000 -> 0.0469 | J8: =I8*C8 -> 1.3601 | K8: ='Cross-layer'!$B$24 -> 80 | L8: =K8/100/100*J8/(1-'Cross-layer'!$B$19) -> 0.011575319 | M8: =K8/100/100*I8*1000 -> 0.3752
A9: Contact layer 2 | B9: NiO | C9: =_xlfn.XLOOKUP(B9,Tabel2[Material],Tabel2[Cost],"Not found") -> 29 | D9: 10 | E9: 0.3 | F9: 1 | G9: =F9*(1-E9) -> 0.7 | H9: =_xlfn.XLOOKUP(B9,Tabel2[Material],Tabel2[Density],"Not found") -> 6.7 | I9: =H9*G9*D9/1000 -> 0.0469 | J9: =I9*C9 -> 1.3601 | K9: ='Cross-layer'!$B$24 -> 80 | L9: =K9/100/100*J9/(1-'Cross-layer'!$B$19) -> 0.011575319 | M9: =K9/100/100*I9*1000 -> 0.3752

Sheet Frame
D1: [€/kg] | E1: [µm] | F1: [%] | I1: [g/cm^3] | J1: [kg/m^2] | K1: [€/m^2] | L1: [cm^2] | M1: [€] | N1: [g]
A2: Layer | B2: Material | C2: Layers per SRU | D2: Mat. Price | E2: Thickness | F2: Porosity | G2: Fraction in layer | H2: Volume% | I2: Mat. Density | J2: Mass | K2: Cost per area | L2: Area | M2: Cost per unit | N2: Mass per unit | Q2: 1 per stack converts to: | R2: =1/'Cross-layer'!B3 -> 0.016666667 | S2: per SRU
A3: Interconnect in SRU | B3: ='Cross-layer'!$B$17 -> Crofer22APU | C3: 1 | D3: =_xlfn.XLOOKUP(B3,Tabel2[Material],Tabel2[Cost],"Not found") -> 25 | E3: ='Cross-layer'!$B$9*C3 -> 300 | F3: 0 | G3: ='Cross-layer'!$B$13 -> 0.97172466 | H3: =G3*(1-F3) -> 0.97172466 | I3: =_xlfn.XLOOKUP(B3,Tabel2[Material],Tabel2[Density],"Not found") -> 7.8 | J3: =I3*E3/1000 -> 2.34 | K3: =J3*D3-(1-H3)*'Cross-layer'!$B$14*D3*J3 -> 58.367671 | L3: ='Cross-layer'!$B$26 -> 124.44 | M3: =L3/100/100*K3 -> 0.7263273 | N3: =L3/100/100*J3*1000 -> 29.11896
A4: Interconnect in stack | B4: ='Cross-layer'!$B$17 -> Crofer22APU | C4: =2*R2 -> 0.033333333 | D4: =_xlfn.XLOOKUP(B4,Tabel2[Material],Tabel2[Cost],"Not found") -> 25 | E4: ='Cross-layer'!$B$9*C4 -> 10 | F4: 0 | G4: ='Cross-layer'!$B$13 -> 0.97172466 | H4: =G4*(1-F4) -> 0.97172466 | I4: =_xlfn.XLOOKUP(B4,Tabel2[Material],Tabel2[Density],"Not found") -> 7.8 | J4: =I4*E4/1000 -> 0.078 | K4: =J4*D4-(1-H4)*'Cross-layer'!$B$14*D4*J4 -> 1.945589 | L4: ='Cross-layer'!$B$26 -> 124.44 | M4: =L4/100/100*K4 -> 0.02421091 | N4: =L4/100/100*J4*1000 -> 0.970632 | Q4: Frame design is based on below layout:
A5: Current collector | B5: ='Cross-layer'!$B$17 -> Crofer22APU | C5: =2*R2 -> 0.033333333 | D5: =_xlfn.XLOOKUP(B5,Tabel2[Material],Tabel2[Cost],"Not found") -> 25 | E5: ='Cross-layer'!$B$10*C5 -> 20 | F5: 0 | G5: ='Cross-layer'!$B$13 -> 0.97172466 | H5: =G5*(1-F5) -> 0.97172466 | I5: =_xlfn.XLOOKUP(B5,Tabel2[Material],Tabel2[Density],"Not found") -> 7.8 | J5: =I5*E5/1000 -> 0.156 | K5: =J5*D5-(1-H5)*'Cross-layer'!$B$15*D5*J5 -> 3.8691233 | L5: ='Cross-layer'!$B$26 -> 124.44 | M5: =L5/100/100*K5 -> 0.048147371 | N5: =L5/100/100*J5*1000 -> 1.941264
A6: Auxiliary spacer | B6: ='Cross-layer'!$B$17 -> Crofer22APU | C6: =3*R2 -> 0.05 | D6: =_xlfn.XLOOKUP(B6,Tabel2[Material],Tabel2[Cost],"Not found") -> 25 | E6: ='Cross-layer'!$B$10*C6 -> 30 | F6: 0 | G6: ='Cross-layer'!$B$12 -> 0.17616053 | H6: =G6*(1-F6) -> 0.17616053 | I6: =_xlfn.XLOOKUP(B6,Tabel2[Material],Tabel2[Density],"Not found") -> 7.8 | J6: =I6*E6/1000 -> 0.234 | K6: =J6*D6-(1-H6)*'Cross-layer'!$B$15*D6*J6 -> 4.5005509 | L6: ='Cross-layer'!$B$26 -> 124.44 | M6: =L6/100/100*K6 -> 0.056004856 | N6: =L6/100/100*J6*1000 -> 2.911896
A7: Oxidant spacer | B7: ='Cross-layer'!$B$17 -> Crofer22APU | C7: =1 -> 1 | D7: =_xlfn.XLOOKUP(B7,Tabel2[Material],Tabel2[Cost],"Not found") -> 25 | E7: ='Cross-layer'!$B$10 -> 600 | F7: 0 | G7: ='Cross-layer'!$B$12 -> 0.17616053 | H7: =G7*(1-F7) -> 0.17616053 | I7: =_xlfn.XLOOKUP(B7,Tabel2[Material],Tabel2[Density],"Not found") -> 7.8 | J7: =I7*E7/1000 -> 4.68 | K7: =J7*D7-(1-H7)*'Cross-layer'!$B$15*D7*J7 -> 90.011019 | L7: ='Cross-layer'!$B$26 -> 124.44 | M7: =L7/100/100*K7 -> 1.1200971 | N7: =L7/100/100*J7*1000 -> 58.23792
A8: Fuel spacer | B8: ='Cross-layer'!$B$17 -> Crofer22APU | C8: 1 | D8: =_xlfn.XLOOKUP(B8,Tabel2[Material],Tabel2[Cost],"Not found") -> 25 | E8: ='Cross-layer'!$B$10 -> 600 | F8: 0 | G8: ='Cross-layer'!$B$12 -> 0.17616053 | H8: =G8*(1-F8) -> 0.17616053 | I8: =_xlfn.XLOOKUP(B8,Tabel2[Material],Tabel2[Density],"Not found") -> 7.8 | J8: =I8*E8/1000 -> 4.68 | K8: =J8*D8-(1-H8)*'Cross-layer'!$B$15*D8*J8 -> 90.011019 | L8: ='Cross-layer'!$B$26 -> 124.44 | M8: =L8/100/100*K8 -> 1.1200971 | N8: =L8/100/100*J8*1000 -> 58.23792
A9: Compression plate | B9: ='Cross-layer'!$B$17 -> Crofer22APU | C9: =2*R2 -> 0.033333333 | D9: =_xlfn.XLOOKUP(B9,Tabel2[Material],Tabel2[Cost],"Not found") -> 25 | E9: =C9*'Cross-layer'!$B$11 -> 166.66667 | F9: 0 | G9: ='Cross-layer'!$B$13 -> 0.97172466 | H9: =G9*(1-F9) -> 0.97172466 | I9: =_xlfn.XLOOKUP(B9,Tabel2[Material],Tabel2[Density],"Not found") -> 7.8 | J9: =I9*E9/1000 -> 1.3 | K9: =J9*D9-(1-H9)*'Cross-layer'!$B$15*D9*J9 -> 32.242694 | L9: ='Cross-layer'!$B$26 -> 124.44 | M9: =L9/100/100*K9 -> 0.40122809 | N9: =L9/100/100*J9*1000 -> 16.1772
Q25: With the thicknesses given in sheet "Cross-layer"

Sheet Misc
C1: [€/kg] | D1: [µm] | E1: [%] | H1: [g/cm^3] | I1: [kg/m^2] | J1: [€/m^2] | K1: [cm^2] | L1: [€] | M1: [g] | Q1: Assumption:
A2: Layer | B2: Material | C2: Mat. Price | D2: Thickness | E2: Porosity | F2: Fraction in layer | G2: Volume% | H2: Mat. Density | I2: Mass | J2: Cost per area | K2: Area | L2: Cost per unit | M2: Mass per unit | Q2: Numbers reverse engineered from Harboe2020
A3: Glass sealant | B3: Glass sealant | C3: =_xlfn.XLOOKUP(B3,Tabel2[Material],Tabel2[Cost],"Not found") -> 37 | D3: =Calculations!B68 -> 700 | E3: 0 | F3: 1 | G3: =F3*(1-E3) -> 1 | H3: =_xlfn.XLOOKUP(B3,Tabel2[Material],Tabel2[Density],"Not found") -> 1.4405886 | I3: =H3*G3*D3/1000 -> 1.008412 | J3: =I3*C3 -> 37.311244 | K3: =Calculations!B70 -> 44.44 | L3: =J3*K3/100/100 -> 0.16581117 | M3: =K3/100/100*I3*1000 -> 4.4813829 | Q3: Thickness of protection layer is thinner than julich, as temperature is assumed lower
A4: Protection coating | B4: MCF | C4: =_xlfn.XLOOKUP(B4,Tabel2[Material],Tabel2[Cost],"Not found") -> 250 | D4: 50 | E4: 0 | F4: 1 | G4: =F4*(1-E4) -> 1 | H4: =_xlfn.XLOOKUP(B4,Tabel2[Material],Tabel2[Density],"Not found") -> 4.9416382 | I4: =H4*G4*D4/1000 -> 0.24708191 | J4: =I4*C4 -> 61.770477 | K4: ='Cross-layer'!B25 -> 99 | L4: =J4*K4/100/100 -> 0.61152772 | M4: =K4/100/100*I4*1000 -> 2.4461109 | Q4: Ni-mesh is calculated per m^2 cost rather than per kg
A5: Ni-Mesh layer | B5: Ni-Mesh | C5: =Materials!I2 -> 27 | K5: ='Cross-layer'!B24 -> 80 | L5: =K5/100/100*C5 -> 0.216

Sheet Manufacturing calc
A1: Process | B1: Category | C1: Scales by | D1: n machines (base) | E1: CAPEX (per machine) | F1: Power (per machine) | G1: Cycle time | H1: Persons/machine | I1: Nr of shifts | J1: Shift time | K1: Max cycle time | L1: n machines (scaled) | M1: Hour-ratio | N1: Scaling factor | O1: CAPEX | P1: Power | Q1: Energy | R1: Factorized CAPEX | S1: Labour cost | T1: Power cost | U1: CAPEX per SRU | V1: Labour per SRU | W1: Power cost per SRU
A2: Hydraulic plate cutter / guillotine | B2: Interconnects and frames | C2: Length | D2: 2 | E2: 84000 | F2: 14 | G2: 5 | H2: 0.2 | I2: 1 | J2: 7.5 | K2: {=IFERROR(INDEX(Max_cycle_table[Takt time],MATCH(1, (Max_cycle_table[Shifts/day]=I2) * (Max_cycle_table[Hours/shift]=J2), 0)),0)} -> 5.7 | L2: =IFERROR(IF(G2>K2,D2*ROUNDUP(G2/K2,0),D2),D2) -> 2 | M2: =IFERROR((G2/K2)*H2*L2*I2,0) -> 0.35087719 | N2: =VLOOKUP(C2,Scale_table[#All],2,FALSE) -> 0.625 | O2: =E2*L2*('Manufacturing inputs'!$B$16+(1-'Manufacturing inputs'!$B$16)*N2) -> 123900 | P2: =F2*L2*N2 -> 17.5 | Q2: =P2*G2 -> 87.5 | R2: =O2*'Manufacturing inputs'!$B$2 -> 4.956 | S2: =(M2*'Manufacturing inputs'!$B$9)/'Manufacturing inputs'!$B$1 -> 6.0687719 | T2: =Q2*'Manufacturing inputs'!$B$8 -> 0.74788194 | U2: =R2/'Manufacturing inputs'!$B$5 -> 0.027381215 | V2: =S2/'Manufacturing inputs'!$B$5 -> 0.033529127 | W2: =T2/'Manufacturing inputs'!$B$5 -> 0.0041319444
A3: Dual die stamper, automatic | B3: Interconnects and frames | C3: Frame | D3: 2 | E3: 100000 | F3: 32 | G3: 5 | H3: 0.2 | I3: 1 | J3: 7.5 | K3: {=IFERROR(INDEX(Max_cycle_table[Takt time],MATCH(1, (Max_cycle_table[Shifts/day]=I3) * (Max_cycle_table[Hours/shift]=J3), 0)),0)} -> 5.7 | L3: =IFERROR(IF(G3>K3,D3*ROUNDUP(G3/K3,0),D3),D3) -> 2 | M3: =IFERROR((G3/K3)*H3*L3*I3,0) -> 0.35087719 | N3: =VLOOKUP(C3,Scale_table[#All],2,FALSE) -> 0.50096618 | O3: =E3*L3*('Manufacturing inputs'!$B$16+(1-'Manufacturing inputs'!$B$16)*N3) -> 130135.27 | P3: =F3*L3*N3 -> 32.061836 | Q3: =P3*G3 -> 160.30918 | R3: =O3*'Manufacturing inputs'!$B$2 -> 5.2054106 | S3: =(M3*'Manufacturing inputs'!$B$9)/'Manufacturing inputs'!$B$1 -> 6.0687719 | T3: =Q3*'Manufacturing inputs'!$B$8 -> 1.3701982 | U3: =R3/'Manufacturing inputs'!$B$5 -> 0.028759175 | V3: =S3/'Manufacturing inputs'!$B$5 -> 0.033529127 | W3: =T3/'Manufacturing inputs'!$B$5 -> 0.0075701557
A4: Pick and place robot / for stamper | B4: Interconnects and frames | C4: Per piece | D4: 2 | E4: 140000 | F4: 2 | G4: 5 | H4: 0 | I4: 0 | K4: {=IFERROR(INDEX(Max_cycle_table[Takt time],MATCH(1, (Max_cycle_table[Shifts/day]=I4) * (Max_cycle_table[Hours/shift]=J4), 0)),0)} -> 0 | L4: =IFERROR(IF(G4>K4,D4*ROUNDUP(G4/K4,0),D4),D4) -> 2 | M4: =IFERROR((G4/K4)*H4*L4*I4,0) -> 0 | N4: =VLOOKUP(C4,Scale_table[#All],2,FALSE) -> 0.99889625 | O4: =E4*L4*('Manufacturing inputs'!$B$16+(1-'Manufacturing inputs'!$B$16)*N4) -> 279783.66 | P4: =F4*L4*N4 -> 3.995585 | Q4: =P4*G4 -> 19.977925 | R4: =O4*'Manufacturing inputs'!$B$2 -> 11.191347 | S4: =(M4*'Manufacturing inputs'!$B$9)/'Manufacturing inputs'!$B$1 -> 0 | T4: =Q4*'Manufacturing inputs'!$B$8 -> 0.17075576 | U4: =R4/'Manufacturing inputs'!$B$5 -> 0.061830644 | V4: =S4/'Manufacturing inputs'!$B$5 -> 0 | W4: =T4/'Manufacturing inputs'!$B$5 -> 0.00094340201
A5: Sand blasting unit | B5: Interconnects and frames | C5: Frame | D5: 1 | E5: 145000 | F5: 12.5 | G5: 3 | H5: 0.2 | I5: 1 | J5: 7.5 | K5: {=IFERROR(INDEX(Max_cycle_table[Takt time],MATCH(1, (Max_cycle_table[Shifts/day]=I5) * (Max_cycle_table[Hours/shift]=J5), 0)),0)} -> 5.7 | L5: =IFERROR(IF(G5>K5,D5*ROUNDUP(G5/K5,0),D5),D5) -> 1 | M5: =IFERROR((G5/K5)*H5*L5*I5,0) -> 0.10526316 | N5: =VLOOKUP(C5,Scale_table[#All],2,FALSE) -> 0.50096618 | O5: =E5*L5*('Manufacturing inputs'!$B$16+(1-'Manufacturing inputs'!$B$16)*N5) -> 94348.068 | P5: =F5*L5*N5 -> 6.2620773 | Q5: =P5*G5 -> 18.786232 | R5: =O5*'Manufacturing inputs'!$B$2 -> 3.7739227 | S5: =(M5*'Manufacturing inputs'!$B$9)/'Manufacturing inputs'!$B$1 -> 1.8206316 | T5: =Q5*'Manufacturing inputs'!$B$8 -> 0.1605701 | U5: =R5/'Manufacturing inputs'!$B$5 -> 0.020850402 | V5: =S5/'Manufacturing inputs'!$B$5 -> 0.010058738 | W5: =T5/'Manufacturing inputs'!$B$5 -> 0.00088712762
A6: Ultrasonic cleaning bath with dryer | B6: Interconnects and frames | C6: Frame | D6: 2 | E6: =240000/2 -> 120000 | F6: 21 | G6: 5.7 | H6: 0.2 | I6: 1 | J6: 7.5 | K6: {=IFERROR(INDEX(Max_cycle_table[Takt time],MATCH(1, (Max_cycle_table[Shifts/day]=I6) * (Max_cycle_table[Hours/shift]=J6), 0)),0)} -> 5.7 | L6: =IFERROR(IF(G6>K6,D6*ROUNDUP(G6/K6,0),D6),D6) -> 2 | M6: =IFERROR((G6/K6)*H6*L6*I6,0) -> 0.4 | N6: =VLOOKUP(C6,Scale_table[#All],2,FALSE) -> 0.50096618 | O6: =E6*L6*('Manufacturing inputs'!$B$16+(1-'Manufacturing inputs'!$B$16)*N6) -> 156162.32 | P6: =F6*L6*N6 -> 21.04058 | Q6: =P6*G6 -> 119.9313 | R6: =O6*'Manufacturing inputs'!$B$2 -> 6.2464928 | S6: =(M6*'Manufacturing inputs'!$B$9)/'Manufacturing inputs'!$B$1 -> 6.9184 | T6: =Q6*'Manufacturing inputs'!$B$8 -> 1.0250795 | U6: =R6/'Manufacturing inputs'!$B$5 -> 0.03451101 | V6: =S6/'Manufacturing inputs'!$B$5 -> 0.038223204 | W6: =T6/'Manufacturing inputs'!$B$5 -> 0.0056634227
A7: Tumbler mixer for protection powder | B7: Interconnects and frames | C7: Frame | D7: 1 | E7: 41400 | F7: 4 | G7: 18.3 | H7: 1 | I7: 0 | K7: {=IFERROR(INDEX(Max_cycle_table[Takt time],MATCH(1, (Max_cycle_table[Shifts/day]=I7) * (Max_cycle_table[Hours/shift]=J7), 0)),0)} -> 0 | L7: =IFERROR(IF(G7>K7,D7*ROUNDUP(G7/K7,0),D7),D7) -> 1 | M7: =1/7.5*1/2*L7 -> 0.066666667 | N7: =VLOOKUP(C7,Scale_table[#All],2,FALSE) -> 0.50096618 | O7: =E7*L7*('Manufacturing inputs'!$B$16+(1-'Manufacturing inputs'!$B$16)*N7) -> 26938 | P7: =F7*L7*N7 -> 2.0038647 | Q7: =P7*G7 -> 36.670725 | R7: =O7*'Manufacturing inputs'!$B$2 -> 1.07752 | S7: =(M7*'Manufacturing inputs'!$B$9)/'Manufacturing inputs'!$B$1 -> 1.1530667 | T7: =Q7*'Manufacturing inputs'!$B$8 -> 0.31343283 | U7: =R7/'Manufacturing inputs'!$B$5 -> 0.0059531492 | V7: =S7/'Manufacturing inputs'!$B$5 -> 0.0063705341 | W7: =T7/'Manufacturing inputs'!$B$5 -> 0.0017316731
A8: APS coating spraying | B8: Interconnects and frames | C8: Frame | D8: 1 | E8: 1660000 | F8: 660 | G8: 4.8 | H8: 0.2 | I8: 1 | J8: 7.5 | K8: {=IFERROR(INDEX(Max_cycle_table[Takt time],MATCH(1, (Max_cycle_table[Shifts/day]=I8) * (Max_cycle_table[Hours/shift]=J8), 0)),0)} -> 5.7 | L8: =IFERROR(IF(G8>K8,D8*ROUNDUP(G8/K8,0),D8),D8) -> 1 | M8: =IFERROR((G8/K8)*H8*L8*I8,0) -> 0.16842105 | N8: =VLOOKUP(C8,Scale_table[#All],2,FALSE) -> 0.50096618 | O8: =E8*L8*('Manufacturing inputs'!$B$16+(1-'Manufacturing inputs'!$B$16)*N8) -> 1080122.7 | P8: =F8*L8*N8 -> 330.63768 | Q8: =P8*G8 -> 1587.0609 | R8: =O8*'Manufacturing inputs'!$B$2 -> 43.204908 | S8: =(M8*'Manufacturing inputs'!$B$9)/'Manufacturing inputs'!$B$1 -> 2.9130105 | T8: =Q8*'Manufacturing inputs'!$B$8 -> 13.564962 | U8: =R8/'Manufacturing inputs'!$B$5 -> 0.23870115 | V8: =S8/'Manufacturing inputs'!$B$5 -> 0.016093981 | W8: =T8/'Manufacturing inputs'!$B$5 -> 0.074944541
A9: Annealing furnace | B9: Interconnects and frames | C9: Frame | D9: 1 | E9: 1020000 | F9: 69 | G9: 12.3 | H9: 0.2 | I9: 3 | J9: 8 | K9: {=IFERROR(INDEX(Max_cycle_table[Takt time],MATCH(1, (Max_cycle_table[Shifts/day]=I9) * (Max_cycle_table[Hours/shift]=J9), 0)),0)} -> 18.3 | L9: =IFERROR(IF(G9>K9,D9*ROUNDUP(G9/K9,0),D9),D9) -> 1 | M9: =IFERROR((G9/K9)*H9*L9,0) -> 0.13442623 | N9: =VLOOKUP(C9,Scale_table[#All],2,FALSE) -> 0.50096618 | O9: =E9*L9*('Manufacturing inputs'!$B$16+(1-'Manufacturing inputs'!$B$16)*N9) -> 663689.86 | P9: =F9*L9*N9 -> 34.566667 | Q9: =P9*G9 -> 425.17 | R9: =O9*'Manufacturing inputs'!$B$2 -> 26.547594 | S9: =(M9*'Manufacturing inputs'!$B$9)/'Manufacturing inputs'!$B$1 -> 2.3250361 | T9: =Q9*'Manufacturing inputs'!$B$8 -> 3.6340225 | U9: =R9/'Manufacturing inputs'!$B$5 -> 0.14667179 | V9: =S9/'Manufacturing inputs'!$B$5 -> 0.012845503 | W9: =T9/'Manufacturing inputs'!$B$5 -> 0.020077472
A10: Integrated automatic inspection | B10: Interconnects and frames | C10: Per piece | D10: 1 | E10: 213000 | F10: 10 | G10: 0 | H10: 0 | I10: 0 | K10: {=IFERROR(INDEX(Max_cycle_table[Takt time],MATCH(1, (Max_cycle_table[Shifts/day]=I10) * (Max_cycle_table[Hours/shift]=J10), 0)),0)} -> 0 | L10: =IFERROR(IF(G10>K10,D10*ROUNDUP(G10/K10,0),D10),D10) -> 1 | M10: =IFERROR((G10/K10)*H10*L10*I10,0) -> 0 | N10: =VLOOKUP(C10,Scale_table[#All],2,FALSE) -> 0.99889625 | O10: =E10*L10*('Manufacturing inputs'!$B$16+(1-'Manufacturing inputs'!$B$16)*N10) -> 212835.43 | P10: =F10*L10*N10 -> 9.9889625 | Q10: =P10*G10 -> 0 | R10: =O10*'Manufacturing inputs'!$B$2 -> 8.5134172 | S10: =(M10*'Manufacturing inputs'!$B$9)/'Manufacturing inputs'!$B$1 -> 0 | T10: =Q10*'Manufacturing inputs'!$B$8 -> 0 | U10: =R10/'Manufacturing inputs'!$B$5 -> 0.047035454 | V10: =S10/'Manufacturing inputs'!$B$5 -> 0 | W10: =T10/'Manufacturing inputs'!$B$5 -> 0
A11: Laser cutting machine | B11: Interconnects and frames | C11: Length | D11: 1 | E11: 120000 | F11: 30 | G11: 1.5 | H11: 0.2 | I11: 1 | J11: 7.5 | K11: ='Manufacturing inputs'!$J$5 -> 342.3 | L11: =IFERROR(IF(G11>K11,D11*ROUNDUP(G11/K11,0),D11),D11) -> 1 | M11: =IFERROR((G11/K11)*H11*L11*I11,0) -> 0.00087642419 | N11: =VLOOKUP(C11,Scale_table[#All],2,FALSE) -> 0.625 | O11: =E11*L11*('Manufacturing inputs'!$B$16+(1-'Manufacturing inputs'!$B$16)*N11) -> 88500 | P11: =F11*L11*N11 -> 18.75 | Q11: =P11*G11 -> 28.125 | R11: =O11*'Manufacturing inputs'!$B$2 -> 3.54 | S11: =(M11*'Manufacturing inputs'!$B$9)/'Manufacturing inputs'!$B$1 -> 0.015158633 | T11: =Q11*'Manufacturing inputs'!$B$8 -> 0.24039063 | U11: =R11/'Manufacturing inputs'!$B$5 -> 0.019558011 | V11: =S11/'Manufacturing inputs'!$B$5 -> 8.3749352e-05 | W11: =T11/'Manufacturing inputs'!$B$5 -> 0.001328125
A12: CNC vertical mill | B12: Interconnects and frames | C12: Frame | D12: 1 | E12: 267000 | F12: 16.3 | G12: 1 | H12: 1 | I12: 1 | J12: 7.5 | K12: ='Manufacturing inputs'!$J$5 -> 342.3 | L12: =IFERROR(IF(G12>K12,D12*ROUNDUP(G12/K12,0),D12),D12) -> 1 | M12: =IFERROR((G12/K12)*H12*L12*I12,0) -> 0.002921414 | N12: =VLOOKUP(C12,Scale_table[#All],2,FALSE) -> 0.50096618 | O12: =E12*L12*('Manufacturing inputs'!$B$16+(1-'Manufacturing inputs'!$B$16)*N12) -> 173730.58 | P12: =F12*L12*N12 -> 8.1657488 | Q12: =P12*G12 -> 8.1657488 | R12: =O12*'Manufacturing inputs'!$B$2 -> 6.9492232 | S12: =(M12*'Manufacturing inputs'!$B$9)/'Manufacturing inputs'!$B$1 -> 0.050528776 | T12: =Q12*'Manufacturing inputs'!$B$8 -> 0.06979447 | U12: =R12/'Manufacturing inputs'!$B$5 -> 0.038393498 | V12: =S12/'Manufacturing inputs'!$B$5 -> 0.00027916451 | W12: =T12/'Manufacturing inputs'!$B$5 -> 0.0003856048
A13: Spot welding machine | B13: Interconnects and frames | C13: Length | D13: 1 | E13: 77000 | F13: 2 | G13: 5.7 | H13: 0.2 | I13: 1 | J13: 7.5 | K13: {=IFERROR(INDEX(Max_cycle_table[Takt time], MATCH(1, (Max_cycle_table[Shifts/day]=I13) * (Max_cycle_table[Hours/shift]=J13), 0)),0)} -> 5.7 | L13: =IFERROR(IF(G13>K13,D13*ROUNDUP(G13/K13,0),D13),D13) -> 1 | M13: =IFERROR((G13/K13)*H13*L13*I13,0) -> 0.2 | N13: =VLOOKUP(C13,Scale_table[#All],2,FALSE) -> 0.625 | O13: =E13*L13*('Manufacturing inputs'!$B$16+(1-'Manufacturing inputs'!$B$16)*N13) -> 56787.5 | P13: =F13*L13*N13 -> 1.25 | Q13: =P13*G13 -> 7.125 | R13: =O13*'Manufacturing inputs'!$B$2 -> 2.2715 | S13: =(M13*'Manufacturing inputs'!$B$9)/'Manufacturing inputs'!$B$1 -> 3.4592 | T13: =Q13*'Manufacturing inputs'!$B$8 -> 0.060898958 | U13: =R13/'Manufacturing inputs'!$B$5 -> 0.012549724 | V13: =S13/'Manufacturing inputs'!$B$5 -> 0.019111602 | W13: =T13/'Manufacturing inputs'!$B$5 -> 0.00033645833
A14: Cutter for nickel mesh | B14: Interconnects and frames | C14: Length | D14: 1 | E14: 65000 | F14: 2 | G14: 1 | H14: 0.2 | I14: 1 | J14: 7.5 | K14: {=IFERROR(INDEX(Max_cycle_table[Takt time], MATCH(1, (Max_cycle_table[Shifts/day]=I14) * (Max_cycle_table[Hours/shift]=J14), 0)),0)} -> 5.7 | L14: =IFERROR(IF(G14>K14,D14*ROUNDUP(G14/K14,0),D14),D14) -> 1 | M14: =IFERROR((G14/K14)*H14*L14*I14,0) -> 0.035087719 | N14: =VLOOKUP(C14,Scale_table[#All],2,FALSE) -> 0.625 | O14: =E14*L14*('Manufacturing inputs'!$B$16+(1-'Manufacturing inputs'!$B$16)*N14) -> 47937.5 | P14: =F14*L14*N14 -> 1.25 | Q14: =P14*G14 -> 1.25 | R14: =O14*'Manufacturing inputs'!$B$2 -> 1.9175 | S14: =(M14*'Manufacturing inputs'!$B$9)/'Manufacturing inputs'!$B$1 -> 0.60687719 | T14: =Q14*'Manufacturing inputs'!$B$8 -> 0.010684028 | U14: =R14/'Manufacturing inputs'!$B$5 -> 0.010593923 | V14: =S14/'Manufacturing inputs'!$B$5 -> 0.0033529127 | W14: =T14/'Manufacturing inputs'!$B$5 -> 5.9027778e-05
A15: Multi-unit dies | B15: Dies | C15: Frame | D15: 1 | E15: 498000 | F15: 0 | G15: 0 | H15: 0 | K15: {=IFERROR(INDEX(Max_cycle_table[Takt time], MATCH(1, (Max_cycle_table[Shifts/day]=I15) * (Max_cycle_table[Hours/shift]=J15), 0)),0)} -> 0 | L15: =IFERROR(IF(G15>K15,D15*ROUNDUP(G15/K15,0),D15),D15) -> 1 | M15: =IFERROR((G15/K15)*H15*L15*I15,0) -> 0 | N15: =VLOOKUP(C15,Scale_table[#All],2,FALSE) -> 0.50096618 | O15: =E15*L15*('Manufacturing inputs'!$B$16+(1-'Manufacturing inputs'!$B$16)*N15) -> 324036.81 | P15: =F15*L15*N15 -> 0 | Q15: =P15*G15 -> 0 | R15: =O15/'Manufacturing inputs'!$B$1 -> 64.807362 | S15: =(M15*'Manufacturing inputs'!$B$9)/'Manufacturing inputs'!$B$1 -> 0 | T15: =Q15*'Manufacturing inputs'!$B$8 -> 0 | U15: =R15/'Manufacturing inputs'!$B$5 -> 0.35805173 | V15: =S15/'Manufacturing inputs'!$B$5 -> 0 | W15: =T15/'Manufacturing inputs'!$B$5 -> 0
A16: Machinery for cell slurry preparation | B16: Cells and glass sealants | C16: Big cell area | D16: 1 | E16: 75000 | F16: 7.5 | G16: 13.7 | L16: =IFERROR(IF(G16>K16,D16*ROUNDUP(G16/K16,0),D16),D16) -> 1 | M16: =1/8*L16 -> 0.125 | N16: =VLOOKUP(C16,Scale_table[#All],2,FALSE) -> 0.64705882 | O16: =E16*L16*('Manufacturing inputs'!$B$16+(1-'Manufacturing inputs'!$B$16)*N16) -> 56470.588 | P16: =F16*L16*N16 -> 4.8529412 | Q16: =P16*G16 -> 66.485294 | R16: =O16*'Manufacturing inputs'!$B$2 -> 2.2588235 | S16: =(M16*'Manufacturing inputs'!$B$9)/'Manufacturing inputs'!$B$1 -> 2.162 | T16: =Q16*'Manufacturing inputs'!$B$8 -> 0.56826458 | U16: =R16/'Manufacturing inputs'!$B$5 -> 0.012479688 | V16: =S16/'Manufacturing inputs'!$B$5 -> 0.011944751 | W16: =T16/'Manufacturing inputs'!$B$5 -> 0.0031395833
A17: Tape casting machines | B17: Cells and glass sealants | C17: Big cell area | D17: 1 | E17: 507000 | F17: 50 | G17: 4.3 | H17: 2 | I17: 1 | J17: 7.5 | K17: {=IFERROR(INDEX(Max_cycle_table[Takt time], MATCH(1, (Max_cycle_table[Shifts/day]=I17) * (Max_cycle_table[Hours/shift]=J17), 0)),0)} -> 5.7 | L17: =IFERROR(IF(G17>K17,D17*ROUNDUP(G17/K17,0),D17),D17) -> 1 | M17: =IFERROR((G17/K17)*H17*L17*I17,0) -> 1.5087719 | N17: =VLOOKUP(C17,Scale_table[#All],2,FALSE) -> 0.64705882 | O17: =E17*L17*('Manufacturing inputs'!$B$16+(1-'Manufacturing inputs'!$B$16)*N17) -> 381741.18 | P17: =F17*L17*N17 -> 32.352941 | Q17: =P17*G17 -> 139.11765 | R17: =O17*'Manufacturing inputs'!$B$2 -> 15.269647 | S17: =(M17*'Manufacturing inputs'!$B$9)/'Manufacturing inputs'!$B$1 -> 26.095719 | T17: =Q17*'Manufacturing inputs'!$B$8 -> 1.1890694 | U17: =R17/'Manufacturing inputs'!$B$5 -> 0.084362691 | V17: =S17/'Manufacturing inputs'!$B$5 -> 0.14417524 | W17: =T17/'Manufacturing inputs'!$B$5 -> 0.0065694444
A18: PCB Loader | B18: Cells and glass sealants | C18: Length | D18: 2 | E18: 9091 | F18: =0.3/2 -> 0.15 | G18: 6.6 | H18: 0 | I18: 0 | K18: {=IFERROR(INDEX(Max_cycle_table[Takt time], MATCH(1, (Max_cycle_table[Shifts/day]=I18) * (Max_cycle_table[Hours/shift]=J18), 0)),0)} -> 0 | L18: =IFERROR(IF(G18>K18,D18*ROUNDUP(G18/K18,0),D18),D18) -> 2 | M18: =IFERROR((G18/K18)*H18*L18*I18,0) -> 0 | N18: =VLOOKUP(C18,Scale_table[#All],2,FALSE) -> 0.625 | O18: =E18*L18*('Manufacturing inputs'!$B$16+(1-'Manufacturing inputs'!$B$16)*N18) -> 13409.225 | P18: =F18*L18*N18 -> 0.1875 | Q18: =P18*G18 -> 1.2375 | R18: =O18*'Manufacturing inputs'!$B$2 -> 0.536369 | S18: =(M18*'Manufacturing inputs'!$B$9)/'Manufacturing inputs'!$B$1 -> 0 | T18: =Q18*'Manufacturing inputs'!$B$8 -> 0.010577187 | U18: =R18/'Manufacturing inputs'!$B$5 -> 0.0029633646 | V18: =S18/'Manufacturing inputs'!$B$5 -> 0 | W18: =T18/'Manufacturing inputs'!$B$5 -> 5.84375e-05
A19: Screen printer (cells, glass sealant tape) | B19: Cells and glass sealants | C19: Frame | D19: 2 | E19: 68170 | F19: 1.5 | G19: 6.6 | H19: 1 | I19: 3 | J19: 7.5 | K19: {=IFERROR(INDEX(Max_cycle_table[Takt time], MATCH(1, (Max_cycle_table[Shifts/day]=I19) * (Max_cycle_table[Hours/shift]=J19), 0)),0)} -> 17.1 | L19: =IFERROR(IF(G19>K19,D19*ROUNDUP(G19/K19,0),D19),D19) -> 2 | M19: =IFERROR((G19/K19)*H19*L19*I19,0) -> 2.3157895 | N19: =VLOOKUP(C19,Scale_table[#All],2,FALSE) -> 0.50096618 | O19: =E19*L19*('Manufacturing inputs'!$B$16+(1-'Manufacturing inputs'!$B$16)*N19) -> 88713.211 | P19: =F19*L19*N19 -> 1.5028986 | Q19: =P19*G19 -> 9.9191304 | R19: =O19*'Manufacturing inputs'!$B$2 -> 3.5485284 | S19: =(M19*'Manufacturing inputs'!$B$9)/'Manufacturing inputs'!$B$1 -> 40.053895 | T19: =Q19*'Manufacturing inputs'!$B$8 -> 0.084781012 | U19: =R19/'Manufacturing inputs'!$B$5 -> 0.019605129 | V19: =S19/'Manufacturing inputs'!$B$5 -> 0.22129224 | W19: =T19/'Manufacturing inputs'!$B$5 -> 0.00046840338
A20: Reflow oven | B20: Cells and glass sealants | C20: Big cell area | D20: 2 | E20: 42500 | F20: 11 | G20: 6.6 | H20: 0 | I20: 0 | K20: {=IFERROR(INDEX(Max_cycle_table[Takt time], MATCH(1, (Max_cycle_table[Shifts/day]=I20) * (Max_cycle_table[Hours/shift]=J20), 0)),0)} -> 0 | L20: =IFERROR(IF(G20>K20,D20*ROUNDUP(G20/K20,0),D20),D20) -> 2 | M20: =IFERROR((G20/K20)*H20*L20*I20,0) -> 0 | N20: =VLOOKUP(C20,Scale_table[#All],2,FALSE) -> 0.64705882 | O20: =E20*L20*('Manufacturing inputs'!$B$16+(1-'Manufacturing inputs'!$B$16)*N20) -> 64000 | P20: =F20*L20*N20 -> 14.235294 | Q20: =P20*G20 -> 93.952941 | R20: =O20*'Manufacturing inputs'!$B$2 -> 2.56 | S20: =(M20*'Manufacturing inputs'!$B$9)/'Manufacturing inputs'!$B$1 -> 0 | T20: =Q20*'Manufacturing inputs'!$B$8 -> 0.80303667 | U20: =R20/'Manufacturing inputs'!$B$5 -> 0.014143646 | V20: =S20/'Manufacturing inputs'!$B$5 -> 0 | W20: =T20/'Manufacturing inputs'!$B$5 -> 0.0044366667
A21: PCB conveyer | B21: Cells and glass sealants | C21: Length | D21: 2 | E21: 3056 | F21: 0.05 | G21: 6.6 | H21: 0 | I21: 0 | K21: {=IFERROR(INDEX(Max_cycle_table[Takt time], MATCH(1, (Max_cycle_table[Shifts/day]=I21) * (Max_cycle_table[Hours/shift]=J21), 0)),0)} -> 0 | L21: =IFERROR(IF(G21>K21,D21*ROUNDUP(G21/K21,0),D21),D21) -> 2 | M21: =IFERROR((G21/K21)*H21*L21*I21,0) -> 0 | N21: =VLOOKUP(C21,Scale_table[#All],2,FALSE) -> 0.625 | O21: =E21*L21*('Manufacturing inputs'!$B$16+(1-'Manufacturing inputs'!$B$16)*N21) -> 4507.6 | P21: =F21*L21*N21 -> 0.0625 | Q21: =P21*G21 -> 0.4125 | R21: =O21*'Manufacturing inputs'!$B$2 -> 0.180304 | S21: =(M21*'Manufacturing inputs'!$B$9)/'Manufacturing inputs'!$B$1 -> 0 | T21: =Q21*'Manufacturing inputs'!$B$8 -> 0.0035257292 | U21: =R21/'Manufacturing inputs'!$B$5 -> 0.0009961547 | V21: =S21/'Manufacturing inputs'!$B$5 -> 0 | W21: =T21/'Manufacturing inputs'!$B$5 -> 1.9479167e-05
A22: Tape cutter/slitter | B22: Cells and glass sealants | C22: Length | D22: 1 | E22: 15000 | F22: 1 | G22: 2 | H22: 1 | I22: 1 | J22: 7.5 | K22: {=IFERROR(INDEX(Max_cycle_table[Takt time], MATCH(1, (Max_cycle_table[Shifts/day]=I22) * (Max_cycle_table[Hours/shift]=J22), 0)),0)} -> 5.7 | L22: =IFERROR(IF(G22>K22,D22*ROUNDUP(G22/K22,0),D22),D22) -> 1 | M22: =IFERROR((G22/K22)*H22*L22*I22,0) -> 0.35087719 | N22: =VLOOKUP(C22,Scale_table[#All],2,FALSE) -> 0.625 | O22: =E22*L22*('Manufacturing inputs'!$B$16+(1-'Manufacturing inputs'!$B$16)*N22) -> 11062.5 | P22: =F22*L22*N22 -> 0.625 | Q22: =P22*G22 -> 1.25 | R22: =O22*'Manufacturing inputs'!$B$2 -> 0.4425 | S22: =(M22*'Manufacturing inputs'!$B$9)/'Manufacturing inputs'!$B$1 -> 6.0687719 | T22: =Q22*'Manufacturing inputs'!$B$8 -> 0.010684028 | U22: =R22/'Manufacturing inputs'!$B$5 -> 0.0024447514 | V22: =S22/'Manufacturing inputs'!$B$5 -> 0.033529127 | W22: =T22/'Manufacturing inputs'!$B$5 -> 5.9027778e-05
A23: Firing kiln (3-shift) | B23: Cells and glass sealants | C23: Big cell area | D23: 1 | E23: 2550000 | F23: 320 | G23: 18.3 | H23: 0.5 | I23: 3 | J23: 8 | K23: {=IFERROR(INDEX(Max_cycle_table[Takt time], MATCH(1, (Max_cycle_table[Shifts/day]=I23) * (Max_cycle_table[Hours/shift]=J23), 0)),0)} -> 18.3 | L23: =IFERROR(IF(G23>K23,D23*ROUNDUP(G23/K23,0),D23),D23) -> 1 | M23: =IFERROR((G23/K23)*H23*L23*I23,0) -> 1.5 | N23: =VLOOKUP(C23,Scale_table[#All],2,FALSE) -> 0.64705882 | O23: =E23*L23*('Manufacturing inputs'!$B$16+(1-'Manufacturing inputs'!$B$16)*N23) -> 1920000 | P23: =F23*L23*N23 -> 207.05882 | Q23: =P23*G23 -> 3789.1765 | R23: =O23*'Manufacturing inputs'!$B$2 -> 76.8 | S23: =(M23*'Manufacturing inputs'!$B$9)/'Manufacturing inputs'!$B$1 -> 25.944 | T23: =Q23*'Manufacturing inputs'!$B$8 -> 32.386933 | U23: =R23/'Manufacturing inputs'!$B$5 -> 0.42430939 | V23: =S23/'Manufacturing inputs'!$B$5 -> 0.14333702 | W23: =T23/'Manufacturing inputs'!$B$5 -> 0.17893333
A24: Machinery for sealent slurry preparation | B24: Cells and glass sealants | C24: Big cell area | D24: 1 | E24: 46875 | F24: 5.5 | G24: 11 | L24: =IFERROR(IF(G24>K24,D24*ROUNDUP(G24/K24,0),D24),D24) -> 1 | M24: =1/7.5*L24 -> 0.13333333 | N24: =VLOOKUP(C24,Scale_table[#All],2,FALSE) -> 0.64705882 | O24: =E24*L24*('Manufacturing inputs'!$B$16+(1-'Manufacturing inputs'!$B$16)*N24) -> 35294.118 | P24: =F24*L24*N24 -> 3.5588235 | Q24: =P24*G24 -> 39.147059 | R24: =O24*'Manufacturing inputs'!$B$2 -> 1.4117647 | S24: =(M24*'Manufacturing inputs'!$B$9)/'Manufacturing inputs'!$B$1 -> 2.3061333 | T24: =Q24*'Manufacturing inputs'!$B$8 -> 0.33459861 | U24: =R24/'Manufacturing inputs'!$B$5 -> 0.007799805 | V24: =S24/'Manufacturing inputs'!$B$5 -> 0.012741068 | W24: =T24/'Manufacturing inputs'!$B$5 -> 0.0018486111
A25: Laser welder | B25: Pre-assembly | C25: Length | D25: 2 | E25: =340000/2 -> 170000 | F25: 5 | G25: 16.2 | H25: 0.2 | I25: 3 | J25: 7.5 | K25: {=IFERROR(INDEX(Max_cycle_table[Takt time], MATCH(1, (Max_cycle_table[Shifts/day]=I25) * (Max_cycle_table[Hours/shift]=J25), 0)),0)} -> 17.1 | L25: =IFERROR(IF(G25>K25,D25*ROUNDUP(G25/K25,0),D25),D25) -> 2 | M25: =IFERROR((G25/K25)*H25*L25*I25,0) -> 1.1368421 | N25: =VLOOKUP(C25,Scale_table[#All],2,FALSE) -> 0.625 | O25: =E25*L25*('Manufacturing inputs'!$B$16+(1-'Manufacturing inputs'!$B$16)*N25) -> 250750 | P25: =F25*L25*N25 -> 6.25 | Q25: =P25*G25 -> 101.25 | R25: =O25*'Manufacturing inputs'!$B$2 -> 10.03 | S25: =(M25*'Manufacturing inputs'!$B$9)/'Manufacturing inputs'!$B$1 -> 19.662821 | T25: =Q25*'Manufacturing inputs'!$B$8 -> 0.86540625 | U25: =R25/'Manufacturing inputs'!$B$5 -> 0.055414365 | V25: =S25/'Manufacturing inputs'!$B$5 -> 0.10863437 | W25: =T25/'Manufacturing inputs'!$B$5 -> 0.00478125
A26: Robot assembly stations | B26: Pre-assembly | C26: Frame | D26: 8 | E26: =720000/8 -> 90000 | F26: 2 | G26: 5.1 | H26: 0.2 | I26: 1 | J26: 7.5 | K26: {=IFERROR(INDEX(Max_cycle_table[Takt time], MATCH(1, (Max_cycle_table[Shifts/day]=I26) * (Max_cycle_table[Hours/shift]=J26), 0)),0)} -> 5.7 | L26: 8 | M26: =IFERROR((G26/K26)*H26*L26*I26,0) -> 1.4315789 | N26: =VLOOKUP(C26,Scale_table[#All],2,FALSE) -> 0.50096618 | O26: =E26*L26*('Manufacturing inputs'!$B$16+(1-'Manufacturing inputs'!$B$16)*N26) -> 468486.96 | P26: =F26*L26*N26 -> 8.0154589 | Q26: =P26*G26 -> 40.878841 | R26: =O26*'Manufacturing inputs'!$B$2 -> 18.739478 | S26: =(M26*'Manufacturing inputs'!$B$9)/'Manufacturing inputs'!$B$1 -> 24.760589 | T26: =Q26*'Manufacturing inputs'!$B$8 -> 0.34940053 | U26: =R26/'Manufacturing inputs'!$B$5 -> 0.10353303 | V26: =S26/'Manufacturing inputs'!$B$5 -> 0.13679884 | W26: =T26/'Manufacturing inputs'!$B$5 -> 0.0019303897
A27: Annealing oven | B27: Pre-assembly | C27: Frame | D27: 1 | E27: 1147500 | F27: 100 | G27: 17.6 | H27: 0.2 | I27: 3 | J27: 8 | K27: {=IFERROR(INDEX(Max_cycle_table[Takt time], MATCH(1, (Max_cycle_table[Shifts/day]=I27) * (Max_cycle_table[Hours/shift]=J27), 0)),0)} -> 18.3 | L27: =IFERROR(IF(G27>K27,D27*ROUNDUP(G27/K27,0),D27),D27) -> 1 | M27: =IFERROR((G27/K27)*H27*L27*I27,0) -> 0.57704918 | N27: =VLOOKUP(C27,Scale_table[#All],2,FALSE) -> 0.50096618 | O27: =E27*L27*('Manufacturing inputs'!$B$16+(1-'Manufacturing inputs'!$B$16)*N27) -> 746651.09 | P27: =F27*L27*N27 -> 50.096618 | Q27: =P27*G27 -> 881.70048 | R27: =O27*'Manufacturing inputs'!$B$2 -> 29.866043 | S27: =(M27*'Manufacturing inputs'!$B$9)/'Manufacturing inputs'!$B$1 -> 9.9806426 | T27: =Q27*'Manufacturing inputs'!$B$8 -> 7.53609 | U27: =R27/'Manufacturing inputs'!$B$5 -> 0.16500577 | V27: =S27/'Manufacturing inputs'!$B$5 -> 0.055141672 | W27: =T27/'Manufacturing inputs'!$B$5 -> 0.041635856
A28: Assembly line | B28: Final assembly | C28: Frame | D28: 1 | E28: 80000 | F28: 0 | G28: 0 | H28: 1.6 | I28: 0 | K28: {=IFERROR(INDEX(Max_cycle_table[Takt time], MATCH(1, (Max_cycle_table[Shifts/day]=I28) * (Max_cycle_table[Hours/shift]=J28), 0)),0)} -> 0 | L28: =IFERROR(IF(G28>K28,D28*ROUNDUP(G28/K28,0),D28),D28) -> 1 | M28: =H28*L28 -> 1.6 | N28: =VLOOKUP(C28,Scale_table[#All],2,FALSE) -> 0.50096618 | O28: =E28*L28*('Manufacturing inputs'!$B$16+(1-'Manufacturing inputs'!$B$16)*N28) -> 52054.106 | P28: =F28*L28*N28 -> 0 | Q28: =P28*G28 -> 0 | R28: =O28*'Manufacturing inputs'!$B$2 -> 2.0821643 | S28: =(M28*'Manufacturing inputs'!$B$9)/'Manufacturing inputs'!$B$1 -> 27.6736 | T28: =Q28*'Manufacturing inputs'!$B$8 -> 0 | U28: =R28/'Manufacturing inputs'!$B$5 -> 0.01150367 | V28: =S28/'Manufacturing inputs'!$B$5 -> 0.15289282 | W28: =T28/'Manufacturing inputs'!$B$5 -> 0
A29: Sintering and testing line | B29: Final assembly | C29: Frame | D29: 1 | E29: 1700000 | F29: 90 | G29: 1 | H29: 2 | I29: 0 | K29: {=IFERROR(INDEX(Max_cycle_table[Takt time], MATCH(1, (Max_cycle_table[Shifts/day]=I29) * (Max_cycle_table[Hours/shift]=J29), 0)),0)} -> 0 | L29: =IFERROR(IF(G29>K29,D29*ROUNDUP(G29/K29,0),D29),D29) -> 1 | M29: =H29*G29*L29 -> 2 | N29: =VLOOKUP(C29,Scale_table[#All],2,FALSE) -> 0.50096618 | O29: =E29*L29*('Manufacturing inputs'!$B$16+(1-'Manufacturing inputs'!$B$16)*N29) -> 1106149.8 | P29: =F29*L29*N29 -> 45.086957 | Q29: =P29*G29*24/24.5 -> 44.166815 | R29: =O29*'Manufacturing inputs'!$B$2 -> 44.24599 | S29: =(M29*'Manufacturing inputs'!$B$9)/'Manufacturing inputs'!$B$1 -> 34.592 | T29: =Q29 -> 44.166815 | U29: =R29/'Manufacturing inputs'!$B$5 -> 0.24445299 | V29: =S29/'Manufacturing inputs'!$B$5 -> 0.19111602 | W29: =T29/'Manufacturing inputs'!$B$5 -> 0.24401555

Sheet Materials
B1: [€/kg] | C1: [g/cm^3] | I1: [€/m^2]
A2: Material | B2: Cost | C2: Density | H2: Ni-Mesh | I2: 27
A3: SS441 | B3: 1.7 | C3: 7.8
A4: 8YSZ | B4: 30 | C4: 6.3
A5: ScYSZ | B5: 90 | C5: 6.3
A6: CGO | B6: 260 | C6: 7.2
A7: LSC | B7: 55 | C7: 6.3
A8: Crofer22APU | B8: 25 | C8: 7.8
A9: Crofer22H | B9: 19 | C9: 7.8
A10: NiO | B10: 29 | C10: 6.7
A11: LSCF | B11: =B7 -> 55 | C11: =C7 -> 6.3
A12: LSFNT | B12: =B7 -> 55 | C12: =C7 -> 6.3
A13: Ni/CGO | B13: =B6 -> 260 | C13: =C6 -> 7.2
A14: Glass sealant | B14: 37 | C14: =Calculations!B65 -> 1.4405886
A15: MCF | B15: 250 | C15: =Calculations!B81 -> 4.9416382
A16: SS441 powder | B16: 5 | C16: 7.8

Sheet LHV
A1: T (°C) | B1: ΔH° (kJ/mol) | C1: ΔS° (J/(K mol)) | D1: ΔG° (kJ/mol) | E1: T (K)
A2: 25 | B2: -241.826 | C2: -44.421 | D2: -228.582 | E2: 298
A3: 50 | B3: -242.077 | C3: -45.229 | D3: -227.461 | E3: 323
A4: 75 | B4: -242.323 | C4: -45.964 | D4: -226.321 | E4: 348
A5: 100 | B5: -242.566 | C5: -46.638 | D5: -225.163 | E5: 373
A6: 125 | B6: -242.806 | C6: -47.26 | D6: -223.989 | E6: 398
A7: 150 | B7: -243.043 | C7: -47.836 | D7: -222.801 | E7: 423
A8: 175 | B8: -243.277 | C8: -48.374 | D8: -221.598 | E8: 448
A9: 200 | B9: -243.508 | C9: -48.877 | D9: -220.382 | E9: 473
A10: 225 | B10: -243.738 | C10: -49.349 | D10: -219.154 | E10: 498
A11: 250 | B11: -243.964 | C11: -49.793 | D11: -217.915 | E11: 523
A12: 275 | B12: -244.189 | C12: -50.213 | D12: -216.665 | E12: 548
A13: 300 | B13: -244.411 | C13: -50.609 | D13: -215.405 | E13: 573
... A41: 1000 | B41: -249.259 | C41: -56.361 | D41: -177.503 | E41: 1273

Sheet Calculations
A1: This sheet is used to estimate the fraction of each metal component, which needs to be cut out in order for other components to fit in
A3: Below are the 2-dimensional measurements for the reference design:
A5: Cell length: | B5: ='Cross-layer'!B4+'Cross-layer'!B6 -> 11 | C5: cm
A6: Cell width: | B6: ='Cross-layer'!B5+'Cross-layer'!B6 -> 9 | C6: cm
A7: Cell ratio | B7: ='Cross-layer'!B6 -> 1
A8: Frame constant | B8: ='Cross-layer'!B7 -> 1.2 | C8: cm
A10: Meaning the total frame is:
A12: Frame length: | B12: ='Cross-layer'!B22 -> 12.2 | C12: cm
A13: Frame width: | B13: ='Cross-layer'!B23 -> 10.2 | C13: cm
A15: All metal layers contain holes for gas flow, which need to be included
A17: Retry:
A19: Fuel hole radius base | B19: =0.4/2 -> 0.2 | C19: cm
A20: Fuel hole area base | B20: =PI()*B19^2 -> 0.12566371 | C20: cm^2
A21: Frame constant base: | B21: 1.2 | C21: cm
A22: Scaler: | B22: =B8/B21 -> 1
A23: Actual area | B23: =B20*B22 -> 0.12566371 | C23: cm^2
A24: Actual radius | B24: =SQRT(B23/PI()) -> 0.2 | C24: cm
A26: Base number of holes | B26: 14
A27: Cell length base | B27: 11 | C27: cm
A28: Scaler | B28: =B5/B27 -> 1
A29: New nr. of holes | B29: =INT(B26*B28) -> 14
A32: A_holes: | B32: =B23*B29*2 -> 3.5185838 | C32: cm^2
A34: Frame area with metal: | B34: =B12*B13-B32 -> 120.92142 | C34: cm^2
A35: % of frame area: | B35: =B34/(B13*B12) -> 0.97172466
A37: Assumption: | B37: Both spacer-layers and interconnect layers have holes cut out for the cell.
A39: Frame area: | B39: =B12*B13 -> 124.44 | C39: cm^2
A40: Cell area: | B40: =B6*B5 -> 99 | C40: cm^2
A42: Metal area: | B42: =B39-B40-B32 -> 21.921416 | C42: cm^2 | D42: (for spacers and IC)
A43: %of frame: | B43: =B42/B39 -> 0.17616053
A45: Harboe stack design: | B45: To reverse-engineer the glass sealant use and density:
A47: Cell area | B47: 128 | C47: cm^2
A48: Cells per stack | B48: 60
A49: Stacks per 5kW | B49: 3.02
A50: Total cells per 5kW | B50: =B49*B48 -> 181.2
A51: Total glass sealant | B51: 2.2 | C51: kg
A52: Glass sealant per cell | B52: =B51/B50 -> 0.01214128 | C52: kg
B53: =B52*1000 -> 12.14128 | C53: g
A55: Total sealant height | B55: 700 | C55: [µm] | D55: (from source:) | F55: https://juser.fz-juelich.de/record/842212/files/Energie_Umwelt_391.pdf
A57: Dimensions:
A58: Length | B58: 180 | C58: mm
...
