Workbook

Sheet Results
B1: Cost | C1: Unit | D1: Cost | E1: Unit | F1: Mass | G1: Unit | I1: Comparison:
A2: Total costs | B2: =SUM(B4:B9) -> 0.11183324 | C2: €/cm^2 | D2: =SUM(D4:D9) -> 15.078317 | E2: €/SRU | F2: =SUM(F4:F6) -> 380.8683 | G2: g/SRU | I2: Harboe: | J2: =SUM(J4:J8) -> 16
M3: Harboe | N3: This model
A4: Cell | B4: =SUM(Cell!L3:L1048576)/'Cross-layer'!B24 -> 0.010094673 | C4: €/cm^2 | D4: =SUM(Cell!L3:L1048576) -> 1.2921182 | E4: €/SRU | F4: =SUM(Cell!M3:M1048576) -> 29.458574 | G4: g/SRU | I4: Cell | J4: 1.46 | K4: €/SRU | L4: Cell | M4: =J4/'Cross-layer'!$B$24 -> 0.01140625 | N4: =B4 -> 0.010094673 | O4: €/cm^2
A5: Frame | B5: =SUM(Frame!M3:M1048576)/'Cross-layer'!B24 -> 0.042479524 | C5: €/cm^2 | D5: =SUM(Frame!M3:M1048576) -> 5.437379 | E5: €/SRU | F5: =SUM(Frame!N3:N1048576) -> 331.90539 | G5: g/SRU | I5: Frame | J5: 5.51 | K5: €/SRU | L5: Frame | M5: =J5/'Cross-layer'!$B$24 -> 0.043046875 | N5: =B5 -> 0.042479524 | O5: €/cm^2
A6: Miscellaneous | B6: =SUM(Misc!L3:L1048576)/'Cross-layer'!B24 -> 0.020919461 | C6: €/cm^2 | D6: =SUM(Misc!L3:L1048576) -> 2.677691 | E6: €/SRU | F6: =SUM(Misc!M3:M1048576) -> 19.504338 | G6: g/SRU | I6: Misc | J6: 3.43 | K6: €/SRU | L6: Misc | M6: =J6/'Cross-layer'!$B$24 -> 0.026796875 | N6: =B6 -> 0.020919461 | O6: €/cm^2
A7: Machining | B7: =D7/'Cross-layer'!B24 -> 0.02474994 | C7: €/cm^2 | D7: =SUM('Manufacturing calc'!U:U) -> 3.1679923 | E7: €/SRU | I7: Labour | J7: 1.44 | K7: €/SRU | L7: Labour | M7: =J7/'Cross-layer'!$B$24 -> 0.01125 | N7: =B8 -> 0.0090528157 | O7: €/cm^2
A8: Labour | B8: =D8/'Cross-layer'!B25 -> 0.0090528157 | C8: €/cm^2 | D8: =SUM('Manufacturing calc'!V:V) -> 1.3850808 | E8: €/SRU | I8: Other | J8: 4.16 | K8: €/SRU | L8: Other | M8: =J8/'Cross-layer'!$B$24 -> 0.0325 | N8: =B9+B7 -> 0.029286765 | O8: €/cm^2
A9: Energy | B9: =D9/'Cross-layer'!B26 -> 0.0045368253 | C9: €/cm^2 | D9: =SUM('Manufacturing calc'!W:W) -> 1.1180552 | E9: €/SRU
A12: Further breakdown:
A13: Cell: | B13: €/cm^2 | C13: €/SRU
A14: Oxygen electrode | B14: =Cell!L3/'Cross-layer'!$B$24 -> 0.0012901596 | C14: =B14*'Cross-layer'!$B$24 -> 0.16514043
A15: Contact layer | B15: =Cell!L4/'Cross-layer'!$B$24 -> 0.0025803191 | C15: =B15*'Cross-layer'!$B$24 -> 0.33028085
A16: CGO Layer | B16: =Cell!L6/'Cross-layer'!$B$24 -> 0.0011951853 | C16: =B16*'Cross-layer'!$B$24 -> 0.15298372
A17: Electrolyte | B17: =Cell!L7/'Cross-layer'!$B$24 -> 0.00024033411 | C17: =B17*'Cross-layer'!$B$24 -> 0.030762766
A18: Ni-YSZ Active | B18: =(Cell!L8+Cell!L9)/'Cross-layer'!$B$24 -> 0.00011886783 | C18: =B18*'Cross-layer'!$B$24 -> 0.015215082
A19: Ni-YSZ Support | B19: =(Cell!L10+Cell!L11)/'Cross-layer'!$B$24 -> 0.0046698075 | C19: =B19*'Cross-layer'!$B$24 -> 0.59773535
A21: Frame: | B21: €/cm^2 | C21: €/SRU
A22: Interconnects | B22: =(Frame!M3+Frame!M4)/'Cross-layer'!B24 -> 0.008804858 | C22: =B22*'Cross-layer'!$B$24 -> 1.1270218
A23: Spacers | B23: =(Frame!M6+Frame!M7+Frame!M8)/'Cross-layer'!B24 -> 0.028433652 | C23: =B23*'Cross-layer'!$B$24 -> 3.6395074
A24: Current collectors | B24: =Frame!M5/'Cross-layer'!B24 -> 0.00056153718 | C24: =B24*'Cross-layer'!$B$24 -> 0.071876759
A25: Compression plates | B25: =Frame!M9/'Cross-layer'!B24 -> 0.0046794765 | C25: =B25*'Cross-layer'!$B$24 -> 0.59897299
A27: Misc: | B27: €/cm^2 | C27: €/SRU
A28: Glass sealant | B28: =Misc!L3/'Cross-layer'!$B$24 -> 0.003452456 | C28: =Misc!L3 -> 0.44191437
A29: Protection coating | B29: =Misc!L4/'Cross-layer'!$B$24 -> 0.014767005 | C29: =Misc!L4 -> 1.8901766
A30: Ni-Mesh layer | B30: =Misc!L5/'Cross-layer'!$B$24 -> 0.0027 | C30: =Misc!L5 -> 0.3456
A32: Manufacturing and labour: | B32: Machine costs | C32: Labour | D32: Energy | E32: Total | F32: €/cm^2
A33: Interconnects and frames | B33: =SUMIF('Manufacturing calc'!$B:$B,Results!$A33,'Manufacturing calc'!U:U) -> 0.98732816 | C33: =SUMIF('Manufacturing calc'!$B:$B,Results!$A33,'Manufacturing calc'!V:V) -> 0.17347764 | D33: =SUMIF('Manufacturing calc'!$B:$B,Results!$A33,'Manufacturing calc'!W:W) -> 0.23159412 | E33: =SUM(B33:D33) -> 1.3923999 | F33: =E33/'Cross-layer'!$B$26 -> 0.0056500565
A34: Dies | B34: =SUMIF('Manufacturing calc'!$B:$B,Results!$A34,'Manufacturing calc'!U:U) -> 0.54593429 | C34: =SUMIF('Manufacturing calc'!$B:$B,Results!$A34,'Manufacturing calc'!V:V) -> 0 | D34: =SUMIF('Manufacturing calc'!$B:$B,Results!$A34,'Manufacturing calc'!W:W) -> 0 | E34: =SUM(B34:D34) -> 0.54593429 | F34: =E34/'Cross-layer'!$B$26 -> 0.0022152828
A35: Cells and glass sealants | B35: =SUMIF('Manufacturing calc'!$B:$B,Results!$A35,'Manufacturing calc'!U:U) -> 0.75987474 | C35: =SUMIF('Manufacturing calc'!$B:$B,Results!$A35,'Manufacturing calc'!V:V) -> 0.56701944 | D35: =SUMIF('Manufacturing calc'!$B:$B,Results!$A35,'Manufacturing calc'!W:W) -> 0.30928637 | E35: =SUM(B35:D35) -> 1.6361806 | F35: =E35/'Cross-layer'!$B$26 -> 0.0066392654
A36: Pre-assembly | B36: =SUMIF('Manufacturing calc'!$B:$B,Results!$A36,'Manufacturing calc'!U:U) -> 0.48458884 | C36: =SUMIF('Manufacturing calc'!$B:$B,Results!$A36,'Manufacturing calc'!V:V) -> 0.30057488 | D36: =SUMIF('Manufacturing calc'!$B:$B,Results!$A36,'Manufacturing calc'!W:W) -> 0.093928252 | E36: =SUM(B36:D36) -> 0.87909197 | F36: =E36/'Cross-layer'!$B$26 -> 0.0035671643
A37: Final assembly | B37: =SUMIF('Manufacturing calc'!$B:$B,Results!$A37,'Manufacturing calc'!U:U) -> 0.39026628 | C37: =SUMIF('Manufacturing calc'!$B:$B,Results!$A37,'Manufacturing calc'!V:V) -> 0.34400884 | D37: =SUMIF('Manufacturing calc'!$B:$B,Results!$A37,'Manufacturing calc'!W:W) -> 0.48324648 | E37: =SUM(B37:D37) -> 1.2175216 | F37: =E37/'Cross-layer'!$B$26 -> 0.0049404382

Sheet Manufacturing inputs
A1: Production volume | B1: 5000 | C1: batches | F1: Table for max cycle time | G1: Shifts/day | H1: Hours/shift | I1: Hours/year | J1: Takt time
A2: Machine cost factor (CAPEX) | B2: =0.2/B1 -> 4e-05 | F2: Takt time, 1 shift (7.5 hrs) | G2: 1 | H2: 7.5 | I2: =$B$12*Max_cycle_table[[#This Row],[Shifts/day]]*Max_cycle_table[[#This Row],[Hours/shift]]*$B$11 -> 1434.375 | J2: =ROUND(I2*60^2/$B$14,1) -> 5.7
A3: Stacks per batch | B3: ='Cross-layer'!B27 -> 3.0166667 | F3: Takt time, 3 shift (7.5 hrs) | G3: 3 | H3: 7.5 | I3: =$B$12*Max_cycle_table[[#This Row],[Shifts/day]]*Max_cycle_table[[#This Row],[Hours/shift]]*$B$11 -> 4303.125 | J3: =ROUND(I3*60^2/$B$14,1) -> 17.1
A4: SRU per stack | B4: ='Cross-layer'!B3 -> 60 | F4: Takt time, 3 shift (8 hrs) | G4: 3 | H4: 8 | I4: =$B$12*Max_cycle_table[[#This Row],[Shifts/day]]*Max_cycle_table[[#This Row],[Hours/shift]]*$B$11 -> 4590 | J4: =ROUND(I4*60^2/$B$14,1) -> 18.3
A5: Layers per batch | B5: =B3*B4 -> 181 | F5: End plates | G5: 1 | H5: 7.5 | I5: =$B$12*Max_cycle_table[[#This Row],[Shifts/day]]*Max_cycle_table[[#This Row],[Hours/shift]]*$B$11 -> 1434.375 | J5: =ROUND(I5*60^2/(B3*B1),1) -> 342.3
A6: Power price | B6: 0.17 | C6: €/kWh
A7: Power cost per batch | B7: =B6*B5 -> 30.77 | C7: €/kWh
A8: -II- in kJ | B8: =B7/3600 -> 0.0085472222 | C8: €/kJ
A9: Annual salary, per labourer | B9: 86480 | C9: €/year
A11: Availability factor | B11: 0.85 | C11: [%]
A12: Work days per year | B12: 225 | C12: days/year
A14: Total SRU produced / year | B14: =B1*B5 -> 905000 | C14: SRU/year
A16: Scaling factors | B16: Value
A17: Big cell area | B17: ='Cross-layer'!B25*B25 -> 1
A18: Length | B18: =B27*'Cross-layer'!B4 -> 1
A19: Frame | B19: =B26*'Cross-layer'!B26 -> 0.9921095
A20: Per piece | B20: =B24*B5 -> 0.99889625
A22: Assumed 30.000 pieces before replacement
A24: Scaler, per piece | B24: =1/B42 -> 0.0055187638
A25: Scaler, big cell: | B25: =1/B38 -> 0.0065359477
A26: Scaler, frame: | B26: =1/B39 -> 0.0040257649
A27: Scaler, length: | B27: =1/B34 -> 0.0625
A29: For scaling factors:
A31: Harboe design parameters:
A32: Total length | B32: 18 | C32: cm
A33: Total width | B33: 13.8 | C33: cm
A34: Cell length | B34: 16 | C34: cm
A35: Cell width | B35: 8 | C35: cm
A36: SRU's per stack | B36: 60
A37: Small active area | B37: =B34*B35 -> 128 | C37: cm^2
A38: Big active area | B38: =(B34+'Cross-layer'!B6)*('Manufacturing inputs'!B35+'Cross-layer'!B6) -> 153
A39: Frame area | B39: =B32*B33 -> 248.4 | C39: cm^2
A40: cell_ratio: | B40: =B38/B37 -> 1.1953125
A41: frame_ratio: | B41: =B39/B37 -> 1.940625
A42: Layers per batch | B42: =B36*3.02 -> 181.2

Sheet Cross-layer
A1: Key Values | B1: Input value | C1: Unit
A2: Cells per SRU | B2: 1
A3: SRU per stack | B3: 60
A4: Length | B4: 16 | C4: cm
A5: Width | B5: 8 | C5: cm
A6: Small->Big cell | B6: 1 | C6: cm
A7: Big cell->Frame | B7: 3.2 | C7: cm
A8: Framing
A9: IC Thickness | B9: 300 | C9: µm
A10: Distance between IC | B10: 600 | C10: µm
A11: Compression Thickness | B11: 5000 | C11: µm
A12: Spacer steel fraction | B12: =IF(B18="Without",1,Calculations!B43) -> 0.32204863
A13: Compr/IC/collector steel fraction | B13: =IF(B18="Without",1,Calculations!B35) -> 0.9428894
A14: Scrap cost return (IC) | B14: 0.08
A15: Scrap cost return (other) | B15: 0.28
A16: Decision variables:
A17: Steel material | B17: Crofer22H
A18: With/Without reuse of cutouts | B18: With
A19: Cell discard rate | B19: 0.06
A21: Total footprint
A22: Length | B22: =B4+B6+B7 -> 20.2
A23: Width | B23: =B5+B6+B7 -> 12.2
A24: Small cell area | B24: =B4*B5 -> 128
A25: Big cell area | B25: =(B4+B6)*(B5+B6) -> 153
A26: Frame area | B26: =(B4+B6+B7)*(B5+B6+B7) -> 246.44
A27: Stacks per batch | B27: =181/B3 -> 3.0166667
B38: =(B34+'Cross-layer'!B6)*('Manufacturing inputs'!B35+'Cross-layer'!B5) -> 16

Sheet Cell
C1: [€/kg] | D1: [µm] | E1: [%] | H1: [g/cm^3] | I1: [kg/m^2] | J1: [€/m^2] | K1: [cm^2] | L1: [€] | M1: [g] | O1: Assumptions:
A2: Layer | B2: Material | C2: Mat. Price | D2: Thickness | E2: Porosity | F2: Fraction in layer | G2: Volume% | H2: Mat. Density | I2: Mass | J2: Cost per area | K2: Area | L2: Cost per unit | M2: Mass per unit | O2: Cost of LSC = LSCF = LSFNT
A3: Oxygen electrode | B3: LSC | C3: =_xlfn.XLOOKUP(B3,Tabel2[Material],Tabel2[Cost],"Not found") -> 55 | D3: 50 | E3: 0.3 | F3: 1 | G3: =F3*(1-E3) -> 0.7 | H3: =_xlfn.XLOOKUP(B3,Tabel2[Material],Tabel2[Density],"Not found") -> 6.3 | I3: =H3*G3*D3/1000 -> 0.2205 | J3: =I3*C3 -> 12.1275 | K3: ='Cross-layer'!$B$24 -> 128 | L3: =K3/100/100*J3/(1-'Cross-layer'!$B$19) -> 0.16514043 | M3: =K3/100/100*I3*1000 -> 2.8224 | O3: Cost of Ni/CGO = CGO
A4: Contact layer | B4: LSC | C4: =_xlfn.XLOOKUP(B4,Tabel2[Material],Tabel2[Cost],"Not found") -> 55 | D4: 100 | E4: 0.3 | F4: 1 | G4: =F4*(1-E4) -> 0.7 | H4: =_xlfn.XLOOKUP(B4,Tabel2[Material],Tabel2[Density],"Not found") -> 6.3 | I4: =H4*G4*D4/1000 -> 0.441 | J4: =I4*C4 -> 24.255 | K4: ='Cross-layer'!$B$24 -> 128 | L4: =K4/100/100*J4/(1-'Cross-layer'!$B$19) -> 0.33028085 | M4: =K4/100/100*I4*1000 -> 5.6448 | O4: Ni/CGO cost/density is negligible
B5: CGO | C5: =_xlfn.XLOOKUP(B5,Tabel2[Material],Tabel2[Cost],"Not found") -> 260 | D5: 100 | E5: 0.3
A6: CGO Layer | B6: CGO | C6: =_xlfn.XLOOKUP(B6,Tabel2[Material],Tabel2[Cost],"Not found") -> 260 | D6: 5 | E6: 0 | F6: 1 | G6: =F6*(1-E6) -> 1 | H6: =_xlfn.XLOOKUP(B6,Tabel2[Material],Tabel2[Density],"Not found") -> 7.23 | I6: =H6*G6*D6/1000 -> 0.03615 | J6: =I6*C6 -> 9.399 | K6: ='Cross-layer'!$B$25 -> 153 | L6: =K6/100/100*J6/(1-'Cross-layer'!$B$19) -> 0.15298372 | M6: =K6/100/100*I6*1000 -> 0.553095
A7: Electrolyte | B7: 8YSZ | C7: =_xlfn.XLOOKUP(B7,Tabel2[Material],Tabel2[Cost],"Not found") -> 30 | D7: 10 | E7: 0 | F7: 1 | G7: =F7*(1-E7) -> 1 | H7: =_xlfn.XLOOKUP(B7,Tabel2[Material],Tabel2[Density],"Not found") -> 6.3 | I7: =H7*G7*D7/1000 -> 0.063 | J7: =I7*C7 -> 1.89 | K7: ='Cross-layer'!$B$25 -> 153 | L7: =K7/100/100*J7/(1-'Cross-layer'!$B$19) -> 0.030762766 | M7: =K7/100/100*I7*1000 -> 0.9639
A8: Ni-YSZ Active | B8: 8YSZ | C8: =_xlfn.XLOOKUP(B8,Tabel2[Material],Tabel2[Cost],"Not found") -> 30 | D8: 7 | E8: 0.3 | F8: 0.6 | G8: =F8*(1-E8) -> 0.42 | H8: =_xlfn.XLOOKUP(B8,Tabel2[Material],Tabel2[Density],"Not found") -> 6.3 | I8: =H8*G8*D8/1000 -> 0.018522 | J8: =I8*C8 -> 0.55566 | K8: ='Cross-layer'!$B$25 -> 153 | L8: =K8/100/100*J8/(1-'Cross-layer'!$B$19) -> 0.0090442532 | M8: =K8/100/100*I8*1000 -> 0.2833866
B9: NiO | C9: =_xlfn.XLOOKUP(B9,Tabel2[Material],Tabel2[Cost],"Not found") -> 29 | D9: 7 | E9: 0.3 | F9: 0.4 | G9: =F9*(1-E9) -> 0.28 | H9: =_xlfn.XLOOKUP(B9,Tabel2[Material],Tabel2[Density],"Not found") -> 6.67 | I9: =H9*G9*D9/1000 -> 0.0130732 | J9: =I9*C9 -> 0.3791228 | K9: ='Cross-layer'!$B$25 -> 153 | L9: =K9/100/100*J9/(1-'Cross-layer'!$B$19) -> 0.0061708286 | M9: =K9/100/100*I9*1000 -> 0.20001996
A10: Ni-YSZ Support | B10: 8YSZ | C10: =_xlfn.XLOOKUP(B10,Tabel2[Material],Tabel2[Cost],"Not found") -> 30 | D10: 275 | E10: 0.3 | F10: 0.6 | G10: =F10*(1-E10) -> 0.42 | H10: =_xlfn.XLOOKUP(B10,Tabel2[Material],Tabel2[Density],"Not found") -> 6.3 | I10: =H10*G10*D10/1000 -> 0.72765 | J10: =I10*C10 -> 21.8295 | K10: ='Cross-layer'!$B$25 -> 153 | L10: =K10/100/100*J10/(1-'Cross-layer'!$B$19) -> 0.35530995 | M10: =K10/100/100*I10*1000 -> 11.133045
B11: NiO | C11: =_xlfn.XLOOKUP(B11,Tabel2[Material],Tabel2[Cost],"Not found") -> 29 | D11: 275 | E11: 0.3 | F11: 0.4 | G11: =F11*(1-E11) -> 0.28 | H11: =_xlfn.XLOOKUP(B11,Tabel2[Material],Tabel2[Density],"Not found") -> 6.67 | I11: =H11*G11*D11/1000 -> 0.51359 | J11: =I11*C11 -> 14.89411 | K11: ='Cross-layer'!$B$25 -> 153 | L11: =K11/100/100*J11/(1-'Cross-layer'!$B$19) -> 0.24242541 | M11: =K11/100/100*I11*1000 -> 7.857927

Sheet Frame
D1: [€/kg] | E1: [µm] | F1: [%] | I1: [g/cm^3] | J1: [kg/m^2] | K1: [€/m^2] | L1: [cm^2] | M1: [€] | N1: [g]
A2: Layer | B2: Material | C2: Layers per SRU | D2: Mat. Price | E2: Thickness | F2: Porosity | G2: Fraction in layer | H2: Volume% | I2: Mat. Density | J2: Mass | K2: Cost per area | L2: Area | M2: Cost per unit | N2: Mass per unit | Q2: 1 per stack converts to: | R2: =1/'Cross-layer'!B3 -> 0.016666667 | S2: per SRU
A3: Interconnect in SRU | B3: ='Cross-layer'!$B$17 -> Crofer22H | C3: 1 | D3: =_xlfn.XLOOKUP(B3,Tabel2[Material],Tabel2[Cost],"Not found") -> 19 | E3: ='Cross-layer'!$B$9*C3 -> 300 | F3: 0 | G3: ='Cross-layer'!$B$13 -> 0.9428894 | H3: =G3*(1-F3) -> 0.9428894 | I3: =_xlfn.XLOOKUP(B3,Tabel2[Material],Tabel2[Density],"Not found") -> 7.8 | J3: =I3*E3/1000 -> 2.34 | K3: =J3*D3-(1-H3)*'Cross-layer'!$B$14*D3*J3 -> 44.256869 | L3: ='Cross-layer'!$B$26 -> 246.44 | M3: =L3/100/100*K3 -> 1.0906663 | N3: =L3/100/100*J3*1000 -> 57.66696
A4: Interconnect in stack | B4: ='Cross-layer'!$B$17 -> Crofer22H | C4: =2*R2 -> 0.033333333 | D4: =_xlfn.XLOOKUP(B4,Tabel2[Material],Tabel2[Cost],"Not found") -> 19 | E4: ='Cross-layer'!$B$9*C4 -> 10 | F4: 0 | G4: ='Cross-layer'!$B$13 -> 0.9428894 | H4: =G4*(1-F4) -> 0.9428894 | I4: =_xlfn.XLOOKUP(B4,Tabel2[Material],Tabel2[Density],"Not found") -> 7.8 | J4: =I4*E4/1000 -> 0.078 | K4: =J4*D4-(1-H4)*'Cross-layer'!$B$14*D4*J4 -> 1.475229 | L4: ='Cross-layer'!$B$26 -> 246.44 | M4: =L4/100/100*K4 -> 0.036355543 | N4: =L4/100/100*J4*1000 -> 1.922232
A5: Current collector | B5: ='Cross-layer'!$B$17 -> Crofer22H | C5: =2*R2 -> 0.033333333 | D5: =_xlfn.XLOOKUP(B5,Tabel2[Material],Tabel2[Cost],"Not found") -> 19 | E5: ='Cross-layer'!$B$10*C5 -> 20 | F5: 0 | G5: ='Cross-layer'!$B$13 -> 0.9428894 | H5: =G5*(1-F5) -> 0.9428894 | I5: =_xlfn.XLOOKUP(B5,Tabel2[Material],Tabel2[Density],"Not found") -> 7.8 | J5: =I5*E5/1000 -> 0.156 | K5: =J5*D5-(1-H5)*'Cross-layer'!$B$15*D5*J5 -> 2.9166028 | L5: ='Cross-layer'!$B$26 -> 246.44 | M5: =L5/100/100*K5 -> 0.071876759 | N5: =L5/100/100*J5*1000 -> 3.844464
A6: Auxiliary spacer | B6: ='Cross-layer'!$B$17 -> Crofer22H | C6: =3*R2 -> 0.05 | D6: =_xlfn.XLOOKUP(B6,Tabel2[Material],Tabel2[Cost],"Not found") -> 19 | E6: ='Cross-layer'!$B$10*C6 -> 30 | F6: 0 | G6: ='Cross-layer'!$B$12 -> 0.32204863 | H6: =G6*(1-F6) -> 0.32204863 | I6: =_xlfn.XLOOKUP(B6,Tabel2[Material],Tabel2[Density],"Not found") -> 7.8 | J6: =I6*E6/1000 -> 0.234 | K6: =J6*D6-(1-H6)*'Cross-layer'!$B$15*D6*J6 -> 3.6020319 | L6: ='Cross-layer'!$B$26 -> 246.44 | M6: =L6/100/100*K6 -> 0.088768474 | N6: =L6/100/100*J6*1000 -> 5.766696
A7: Oxidant spacer | B7: ='Cross-layer'!$B$17 -> Crofer22H | C7: =1 -> 1 | D7: =_xlfn.XLOOKUP(B7,Tabel2[Material],Tabel2[Cost],"Not found") -> 19 | E7: ='Cross-layer'!$B$10 -> 600 | F7: 0 | G7: ='Cross-layer'!$B$12 -> 0.32204863 | H7: =G7*(1-F7) -> 0.32204863 | I7: =_xlfn.XLOOKUP(B7,Tabel2[Material],Tabel2[Density],"Not found") -> 7.8 | J7: =I7*E7/1000 -> 4.68 | K7: =J7*D7-(1-H7)*'Cross-layer'!$B$15*D7*J7 -> 72.040638 | L7: ='Cross-layer'!$B$26 -> 246.44 | M7: =L7/100/100*K7 -> 1.7753695 | N7: =L7/100/100*J7*1000 -> 115.33392
A8: Fuel spacer | B8: ='Cross-layer'!$B$17 -> Crofer22H | C8: 1 | D8: =_xlfn.XLOOKUP(B8,Tabel2[Material],Tabel2[Cost],"Not found") -> 19 | E8: ='Cross-layer'!$B$10 -> 600 | F8: 0 | G8: ='Cross-layer'!$B$12 -> 0.32204863 | H8: =G8*(1-F8) -> 0.32204863 | I8: =_xlfn.XLOOKUP(B8,Tabel2[Material],Tabel2[Density],"Not found") -> 7.8 | J8: =I8*E8/1000 -> 4.68 | K8: =J8*D8-(1-H8)*'Cross-layer'!$B$15*D8*J8 -> 72.040638 | L8: ='Cross-layer'!$B$26 -> 246.44 | M8: =L8/100/100*K8 -> 1.7753695 | N8: =L8/100/100*J8*1000 -> 115.33392
A9: Compression plate | B9: ='Cross-layer'!$B$17 -> Crofer22H | C9: =2*R2 -> 0.033333333 | D9: =_xlfn.XLOOKUP(B9,Tabel2[Material],Tabel2[Cost],"Not found") -> 19 | E9: =C9*'Cross-layer'!$B$11 -> 166.66667 | F9: 0 | G9: ='Cross-layer'!$B$13 -> 0.9428894 | H9: =G9*(1-F9) -> 0.9428894 | I9: =_xlfn.XLOOKUP(B9,Tabel2[Material],Tabel2[Density],"Not found") -> 7.8 | J9: =I9*E9/1000 -> 1.3 | K9: =J9*D9-(1-H9)*'Cross-layer'!$B$15*D9*J9 -> 24.305023 | L9: ='Cross-layer'!$B$26 -> 246.44 | M9: =L9/100/100*K9 -> 0.59897299 | N9: =L9/100/100*J9*1000 -> 32.0372

Sheet Misc
C1: [€/kg] | D1: [µm] | E1: [%] | H1: [g/cm^3] | I1: [kg/m^2] | J1: [€/m^2] | K1: [cm^2] | L1: [€] | M1: [g] | Q1: Assumption:
A2: Layer | B2: Material | C2: Mat. Price | D2: Thickness | E2: Porosity | F2: Fraction in layer | G2: Volume% | H2: Mat. Density | I2: Mass | J2: Cost per area | K2: Area | L2: Cost per unit | M2: Mass per unit | Q2: Numbers reverse engineered from Harboe2020
A3: Glass sealant | B3: Glass sealant | C3: 37 | D3: =Calculations!B68 -> 700 | E3: 0 | F3: 1 | G3: =F3*(1-E3) -> 1 | H3: =Calculations!B65 -> 1.4405886 | I3: =H3*G3*D3/1000 -> 1.008412 | J3: =I3*C3 -> 37.311244 | K3: =Calculations!B70 -> 118.44 | L3: =J3*K3/100/100 -> 0.44191437 | M3: =K3/100/100*I3*1000 -> 11.943632 | Q3: Thickness of protection layer is thinner than julich, as temperature is assumed lower
A4: Protection coating | B4: MCF | C4: 250 | D4: 100 | E4: 0 | F4: 1 | G4: =F4*(1-E4) -> 1 | H4: =Calculations!B81 -> 4.9416382 | I4: =H4*G4*D4/1000 -> 0.49416382 | J4: =I4*C4 -> 123.54095 | K4: ='Cross-layer'!B25 -> 153 | L4: =J4*K4/100/100 -> 1.8901766 | M4: =K4/100/100*I4*1000 -> 7.5607064 | Q4: Ni-mesh is calculated per m^2 cost rather than per kg
A5: Ni-Mesh layer | B5: Ni-Mesh | C5: =Materials!I2 -> 27 | K5: ='Cross-layer'!B24 -> 128 | L5: =K5/100/100*C5 -> 0.3456

Sheet Manufacturing calc
A1: Process | B1: Category | C1: Scales by | D1: n machines (base) | E1: CAPEX (per machine) | F1: Power (per machine) | G1: Cycle time | H1: Persons/machine | I1: Nr of shifts | J1: Shift time | K1: Max cycle time | L1: n machines (scaled) | M1: Hour-ratio | N1: Scaling factor | O1: CAPEX | P1: Power | Q1: Energy | R1: Factorized CAPEX | S1: Labour cost | T1: Power cost | U1: CAPEX per SRU | V1: Labour per SRU | W1: Power cost per SRU
A2: Hydraulic plate cutter / guillotine | B2: Interconnects and frames | C2: Length | D2: 2 | E2: 84000 | F2: 14 | G2: 5 | H2: 0.2 | I2: 1 | J2: 7.5 | K2: {=IFERROR(INDEX(Max_cycle_table[Takt time],MATCH(1, (Max_cycle_table[Shifts/day]=I2) * (Max_cycle_table[Hours/shift]=J2), 0)),0)} -> 5.7 | L2: =IFERROR(IF(G2>K2,D2*ROUNDUP(G2/K2,0),D2),D2) -> 2 | M2: =IFERROR((G2/K2)*H2*L2*I2,0) -> 0.35087719 | N2: =VLOOKUP(C2,Scale_table[#All],2,FALSE) -> 1 | O2: =E2*L2*N2 -> 168000 | P2: =F2*L2*N2 -> 28 | Q2: =P2*G2 -> 140 | R2: =O2*'Manufacturing inputs'!$B$2 -> 6.72 | S2: =(M2*'Manufacturing inputs'!$B$9)/'Manufacturing inputs'!$B$1 -> 6.0687719 | T2: =Q2*'Manufacturing inputs'!$B$8 -> 1.1966111 | U2: =R2/'Manufacturing inputs'!$B$5 -> 0.037127072 | V2: =S2/'Manufacturing inputs'!$B$5 -> 0.033529127 | W2: =T2/'Manufacturing inputs'!$B$5 -> 0.0066111111
A3: Dual die stamper, automatic | B3: Interconnects and frames | C3: Frame | D3: 2 | E3: 100000 | F3: 32 | G3: 5 | H3: 0.2 | I3: 1 | J3: 7.5 | K3: {=IFERROR(INDEX(Max_cycle_table[Takt time],MATCH(1, (Max_cycle_table[Shifts/day]=I3) * (Max_cycle_table[Hours/shift]=J3), 0)),0)} -> 5.7 | L3: =IFERROR(IF(G3>K3,D3*ROUNDUP(G3/K3,0),D3),D3) -> 2 | M3: =IFERROR((G3/K3)*H3*L3*I3,0) -> 0.35087719 | N3: =VLOOKUP(C3,Scale_table[#All],2,FALSE) -> 0.9921095 | O3: =E3*L3*N3 -> 198421.9 | P3: =F3*L3*N3 -> 63.495008 | Q3: =P3*G3 -> 317.47504 | R3: =O3*'Manufacturing inputs'!$B$2 -> 7.936876 | S3: =(M3*'Manufacturing inputs'!$B$9)/'Manufacturing inputs'!$B$1 -> 6.0687719 | T3: =Q3*'Manufacturing inputs'!$B$8 -> 2.7135297 | U3: =R3/'Manufacturing inputs'!$B$5 -> 0.043850144 | V3: =S3/'Manufacturing inputs'!$B$5 -> 0.033529127 | W3: =T3/'Manufacturing inputs'!$B$5 -> 0.014991877
A4: Pick and place robot / for stamper | B4: Interconnects and frames | C4: Per piece | D4: 2 | E4: 140000 | F4: 4 | G4: 5 | H4: 0 | I4: 0 | K4: {=IFERROR(INDEX(Max_cycle_table[Takt time],MATCH(1, (Max_cycle_table[Shifts/day]=I4) * (Max_cycle_table[Hours/shift]=J4), 0)),0)} -> 0 | L4: =IFERROR(IF(G4>K4,D4*ROUNDUP(G4/K4,0),D4),D4) -> 2 | M4: =IFERROR((G4/K4)*H4*L4*I4,0) -> 0 | N4: =VLOOKUP(C4,Scale_table[#All],2,FALSE) -> 0.99889625 | O4: =E4*L4*N4 -> 279690.95 | P4: =F4*L4*N4 -> 7.99117 | Q4: =P4*G4 -> 39.95585 | R4: =O4*'Manufacturing inputs'!$B$2 -> 11.187638 | S4: =(M4*'Manufacturing inputs'!$B$9)/'Manufacturing inputs'!$B$1 -> 0 | T4: =Q4*'Manufacturing inputs'!$B$8 -> 0.34151153 | U4: =R4/'Manufacturing inputs'!$B$5 -> 0.061810155 | V4: =S4/'Manufacturing inputs'!$B$5 -> 0 | W4: =T4/'Manufacturing inputs'!$B$5 -> 0.001886804
A5: Sand blasting unit | B5: Interconnects and frames | C5: Frame | D5: 1 | E5: 145000 | F5: 12.5 | G5: 3 | H5: 0.2 | I5: 1 | J5: 7.5 | K5: {=IFERROR(INDEX(Max_cycle_table[Takt time],MATCH(1, (Max_cycle_table[Shifts/day]=I5) * (Max_cycle_table[Hours/shift]=J5), 0)),0)} -> 5.7 | L5: =IFERROR(IF(G5>K5,D5*ROUNDUP(G5/K5,0),D5),D5) -> 1 | M5: =IFERROR((G5/K5)*H5*L5*I5,0) -> 0.10526316 | N5: =VLOOKUP(C5,Scale_table[#All],2,FALSE) -> 0.9921095 | O5: =E5*L5*N5 -> 143855.88 | P5: =F5*L5*N5 -> 12.401369 | Q5: =P5*G5 -> 37.204106 | R5: =O5*'Manufacturing inputs'!$B$2 -> 5.7542351 | S5: =(M5*'Manufacturing inputs'!$B$9)/'Manufacturing inputs'!$B$1 -> 1.8206316 | T5: =Q5*'Manufacturing inputs'!$B$8 -> 0.31799176 | U5: =R5/'Manufacturing inputs'!$B$5 -> 0.031791354 | V5: =S5/'Manufacturing inputs'!$B$5 -> 0.010058738 | W5: =T5/'Manufacturing inputs'!$B$5 -> 0.0017568606
A6: Ultrasonic cleaning bath with dryer | B6: Interconnects and frames | C6: Frame | D6: 2 | E6: =240000/2 -> 120000 | F6: 21 | G6: 5.7 | H6: 0.2 | I6: 1 | J6: 7.5 | K6: {=IFERROR(INDEX(Max_cycle_table[Takt time],MATCH(1, (Max_cycle_table[Shifts/day]=I6) * (Max_cycle_table[Hours/shift]=J6), 0)),0)} -> 5.7 | L6: =IFERROR(IF(G6>K6,D6*ROUNDUP(G6/K6,0),D6),D6) -> 2 | M6: =IFERROR((G6/K6)*H6*L6*I6,0) -> 0.4 | N6: =VLOOKUP(C6,Scale_table[#All],2,FALSE) -> 0.9921095 | O6: =E6*L6*N6 -> 238106.28 | P6: =F6*L6*N6 -> 41.668599 | Q6: =P6*G6 -> 237.51101 | R6: =O6*'Manufacturing inputs'!$B$2 -> 9.5242512 | S6: =(M6*'Manufacturing inputs'!$B$9)/'Manufacturing inputs'!$B$1 -> 6.9184 | T6: =Q6*'Manufacturing inputs'!$B$8 -> 2.0300594 | U6: =R6/'Manufacturing inputs'!$B$5 -> 0.052620172 | V6: =S6/'Manufacturing inputs'!$B$5 -> 0.038223204 | W6: =T6/'Manufacturing inputs'!$B$5 -> 0.011215798
A7: Tumbler mixer for protection powder | B7: Interconnects and frames | C7: Frame | D7: 1 | E7: 41400 | F7: 4 | G7: 18.3 | H7: 1 | I7: 0 | K7: {=IFERROR(INDEX(Max_cycle_table[Takt time],MATCH(1, (Max_cycle_table[Shifts/day]=I7) * (Max_cycle_table[Hours/shift]=J7), 0)),0)} -> 0 | L7: =IFERROR(IF(G7>K7,D7*ROUNDUP(G7/K7,0),D7),D7) -> 1 | M7: =1/7.5*1/2*L7 -> 0.066666667 | N7: =VLOOKUP(C7,Scale_table[#All],2,FALSE) -> 0.9921095 | O7: =E7*L7*N7 -> 41073.333 | P7: =F7*L7*N7 -> 3.968438 | Q7: =P7*G7 -> 72.622415 | R7: =O7*'Manufacturing inputs'!$B$2 -> 1.6429333 | S7: =(M7*'Manufacturing inputs'!$B$9)/'Manufacturing inputs'!$B$1 -> 1.1530667 | T7: =Q7*'Manufacturing inputs'!$B$8 -> 0.62071992 | U7: =R7/'Manufacturing inputs'!$B$5 -> 0.0090769797 | V7: =S7/'Manufacturing inputs'!$B$5 -> 0.0063705341 | W7: =T7/'Manufacturing inputs'!$B$5 -> 0.0034293918
A8: APS coating spraying | B8: Interconnects and frames | C8: Frame | D8: 1 | E8: 1660000 | F8: 660 | G8: 4.8 | H8: 0.2 | I8: 1 | J8: 7.5 | K8: {=IFERROR(INDEX(Max_cycle_table[Takt time],MATCH(1, (Max_cycle_table[Shifts/day]=I8) * (Max_cycle_table[Hours/shift]=J8), 0)),0)} -> 5.7 | L8: =IFERROR(IF(G8>K8,D8*ROUNDUP(G8/K8,0),D8),D8) -> 1 | M8: =IFERROR((G8/K8)*H8*L8*I8,0) -> 0.16842105 | N8: =VLOOKUP(C8,Scale_table[#All],2,FALSE) -> 0.9921095 | O8: =E8*L8*N8 -> 1646901.8 | P8: =F8*L8*N8 -> 654.79227 | Q8: =P8*G8 -> 3143.0029 | R8: =O8*'Manufacturing inputs'!$B$2 -> 65.876071 | S8: =(M8*'Manufacturing inputs'!$B$9)/'Manufacturing inputs'!$B$1 -> 2.9130105 | T8: =Q8*'Manufacturing inputs'!$B$8 -> 26.863944 | U8: =R8/'Manufacturing inputs'!$B$5 -> 0.36395619 | V8: =S8/'Manufacturing inputs'!$B$5 -> 0.016093981 | W8: =T8/'Manufacturing inputs'!$B$5 -> 0.14841958
A9: Annealing furnace | B9: Interconnects and frames | C9: Frame | D9: 1 | E9: 1020000 | F9: 69 | G9: 12.3 | H9: 0.2 | I9: 3 | J9: 8 | K9: {=IFERROR(INDEX(Max_cycle_table[Takt time],MATCH(1, (Max_cycle_table[Shifts/day]=I9) * (Max_cycle_table[Hours/shift]=J9), 0)),0)} -> 18.3 | L9: =IFERROR(IF(G9>K9,D9*ROUNDUP(G9/K9,0),D9),D9) -> 1 | M9: =IFERROR((G9/K9)*H9*L9,0) -> 0.13442623 | N9: =VLOOKUP(C9,Scale_table[#All],2,FALSE) -> 0.9921095 | O9: =E9*L9*N9 -> 1011951.7 | P9: =F9*L9*N9 -> 68.455556 | Q9: =P9*G9 -> 842.00333 | R9: =O9*'Manufacturing inputs'!$B$2 -> 40.478068 | S9: =(M9*'Manufacturing inputs'!$B$9)/'Manufacturing inputs'!$B$1 -> 2.3250361 | T9: =Q9*'Manufacturing inputs'!$B$8 -> 7.1967896 | U9: =R9/'Manufacturing inputs'!$B$5 -> 0.22363573 | V9: =S9/'Manufacturing inputs'!$B$5 -> 0.012845503 | W9: =T9/'Manufacturing inputs'!$B$5 -> 0.039761269
A10: Integrated automatic inspection | B10: Interconnects and frames | C10: Per piece | D10: 1 | E10: 213000 | F10: 10 | G10: 0 | H10: 0 | I10: 0 | K10: {=IFERROR(INDEX(Max_cycle_table[Takt time],MATCH(1, (Max_cycle_table[Shifts/day]=I10) * (Max_cycle_table[Hours/shift]=J10), 0)),0)} -> 0 | L10: =IFERROR(IF(G10>K10,D10*ROUNDUP(G10/K10,0),D10),D10) -> 1 | M10: =IFERROR((G10/K10)*H10*L10*I10,0) -> 0 | N10: =VLOOKUP(C10,Scale_table[#All],2,FALSE) -> 0.99889625 | O10: =E10*L10*N10 -> 212764.9 | P10: =F10*L10*N10 -> 9.9889625 | Q10: =P10*G10 -> 0 | R10: =O10*'Manufacturing inputs'!$B$2 -> 8.510596 | S10: =(M10*'Manufacturing inputs'!$B$9)/'Manufacturing inputs'!$B$1 -> 0 | T10: =Q10*'Manufacturing inputs'!$B$8 -> 0 | U10: =R10/'Manufacturing inputs'!$B$5 -> 0.047019868 | V10: =S10/'Manufacturing inputs'!$B$5 -> 0 | W10: =T10/'Manufacturing inputs'!$B$5 -> 0
A11: Laser cutting machine | B11: Interconnects and frames | C11: Length | D11: 1 | E11: 120000 | F11: 30 | G11: 1.5 | H11: 0.2 | I11: 1 | J11: 7.5 | K11: ='Manufacturing inputs'!$J$5 -> 342.3 | L11: =IFERROR(IF(G11>K11,D11*ROUNDUP(G11/K11,0),D11),D11) -> 1 | M11: =IFERROR((G11/K11)*H11*L11*I11,0) -> 0.00087642419 | N11: =VLOOKUP(C11,Scale_table[#All],2,FALSE) -> 1 | O11: =E11*L11*N11 -> 120000 | P11: =F11*L11*N11 -> 30 | Q11: =P11*G11 -> 45 | R11: =O11*'Manufacturing inputs'!$B$2 -> 4.8 | S11: =(M11*'Manufacturing inputs'!$B$9)/'Manufacturing inputs'!$B$1 -> 0.015158633 | T11: =Q11*'Manufacturing inputs'!$B$8 -> 0.384625 | U11: =R11/'Manufacturing inputs'!$B$5 -> 0.026519337 | V11: =S11/'Manufacturing inputs'!$B$5 -> 8.3749352e-05 | W11: =T11/'Manufacturing inputs'!$B$5 -> 0.002125
A12: CNC vertical mill | B12: Interconnects and frames | C12: Frame | D12: 1 | E12: 267000 | F12: 16.3 | G12: 1 | H12: 1 | I12: 1 | J12: 7.5 | K12: ='Manufacturing inputs'!$J$5 -> 342.3 | L12: =IFERROR(IF(G12>K12,D12*ROUNDUP(G12/K12,0),D12),D12) -> 1 | M12: =IFERROR((G12/K12)*H12*L12*I12,0) -> 0.002921414 | N12: =VLOOKUP(C12,Scale_table[#All],2,FALSE) -> 0.9921095 | O12: =E12*L12*N12 -> 264893.24 | P12: =F12*L12*N12 -> 16.171385 | Q12: =P12*G12 -> 16.171385 | R12: =O12*'Manufacturing inputs'!$B$2 -> 10.595729 | S12: =(M12*'Manufacturing inputs'!$B$9)/'Manufacturing inputs'!$B$1 -> 0.050528776 | T12: =Q12*'Manufacturing inputs'!$B$8 -> 0.13822042 | U12: =R12/'Manufacturing inputs'!$B$5 -> 0.058539942 | V12: =S12/'Manufacturing inputs'!$B$5 -> 0.00027916451 | W12: =T12/'Manufacturing inputs'!$B$5 -> 0.00076364873
A13: Spot welding machine | B13: Interconnects and frames | C13: Length | D13: 1 | E13: 77000 | F13: 2 | G13: 5.7 | H13: 0.2 | I13: 1 | J13: 7.5 | K13: {=IFERROR(INDEX(Max_cycle_table[Takt time], MATCH(1, (Max_cycle_table[Shifts/day]=I13) * (Max_cycle_table[Hours/shift]=J13), 0)),0)} -> 5.7 | L13: =IFERROR(IF(G13>K13,D13*ROUNDUP(G13/K13,0),D13),D13) -> 1 | M13: =IFERROR((G13/K13)*H13*L13*I13,0) -> 0.2 | N13: =VLOOKUP(C13,Scale_table[#All],2,FALSE) -> 1 | O13: =E13*L13*N13 -> 77000 | P13: =F13*L13*N13 -> 2 | Q13: =P13*G13 -> 11.4 | R13: =O13*'Manufacturing inputs'!$B$2 -> 3.08 | S13: =(M13*'Manufacturing inputs'!$B$9)/'Manufacturing inputs'!$B$1 -> 3.4592 | T13: =Q13*'Manufacturing inputs'!$B$8 -> 0.097438333 | U13: =R13/'Manufacturing inputs'!$B$5 -> 0.017016575 | V13: =S13/'Manufacturing inputs'!$B$5 -> 0.019111602 | W13: =T13/'Manufacturing inputs'!$B$5 -> 0.00053833333
A14: Cutter for nickel mesh | B14: Interconnects and frames | C14: Length | D14: 1 | E14: 65000 | F14: 2 | G14: 1 | H14: 0.2 | I14: 1 | J14: 7.5 | K14: {=IFERROR(INDEX(Max_cycle_table[Takt time], MATCH(1, (Max_cycle_table[Shifts/day]=I14) * (Max_cycle_table[Hours/shift]=J14), 0)),0)} -> 5.7 | L14: =IFERROR(IF(G14>K14,D14*ROUNDUP(G14/K14,0),D14),D14) -> 1 | M14: =IFERROR((G14/K14)*H14*L14*I14,0) -> 0.035087719 | N14: =VLOOKUP(C14,Scale_table[#All],2,FALSE) -> 1 | O14: =E14*L14*N14 -> 65000 | P14: =F14*L14*N14 -> 2 | Q14: =P14*G14 -> 2 | R14: =O14*'Manufacturing inputs'!$B$2 -> 2.6 | S14: =(M14*'Manufacturing inputs'!$B$9)/'Manufacturing inputs'!$B$1 -> 0.60687719 | T14: =Q14*'Manufacturing inputs'!$B$8 -> 0.017094444 | U14: =R14/'Manufacturing inputs'!$B$5 -> 0.014364641 | V14: =S14/'Manufacturing inputs'!$B$5 -> 0.0033529127 | W14: =T14/'Manufacturing inputs'!$B$5 -> 9.4444444e-05
A15: Multi-unit dies | B15: Dies | C15: Frame | D15: 1 | E15: 498000 | F15: 0 | G15: 0 | H15: 0 | K15: {=IFERROR(INDEX(Max_cycle_table[Takt time], MATCH(1, (Max_cycle_table[Shifts/day]=I15) * (Max_cycle_table[Hours/shift]=J15), 0)),0)} -> 0 | L15: =IFERROR(IF(G15>K15,D15*ROUNDUP(G15/K15,0),D15),D15) -> 1 | M15: =IFERROR((G15/K15)*H15*L15*I15,0) -> 0 | N15: =VLOOKUP(C15,Scale_table[#All],2,FALSE) -> 0.9921095 | O15: =E15*L15*N15 -> 494070.53 | P15: =F15*L15*N15 -> 0 | Q15: =P15*G15 -> 0 | R15: =O15/'Manufacturing inputs'!$B$1 -> 98.814106 | S15: =(M15*'Manufacturing inputs'!$B$9)/'Manufacturing inputs'!$B$1 -> 0 | T15: =Q15*'Manufacturing inputs'!$B$8 -> 0 | U15: =R15/'Manufacturing inputs'!$B$5 -> 0.54593429 | V15: =S15/'Manufacturing inputs'!$B$5 -> 0 | W15: =T15/'Manufacturing inputs'!$B$5 -> 0
A16: Machinery for cell slurry preparation | B16: Cells and glass sealants | C16: Big cell area | D16: 1 | E16: 75000 | F16: 7.5 | G16: 13.7 | L16: =IFERROR(IF(G16>K16,D16*ROUNDUP(G16/K16,0),D16),D16) -> 1 | M16: =1/8*L16 -> 0.125 | N16: =VLOOKUP(C16,Scale_table[#All],2,FALSE) -> 1 | O16: =E16*L16*N16 -> 75000 | P16: =F16*L16*N16 -> 7.5 | Q16: =P16*G16 -> 102.75 | R16: =O16*'Manufacturing inputs'!$B$2 -> 3 | S16: =(M16*'Manufacturing inputs'!$B$9)/'Manufacturing inputs'!$B$1 -> 2.162 | T16: =Q16*'Manufacturing inputs'!$B$8 -> 0.87822708 | U16: =R16/'Manufacturing inputs'!$B$5 -> 0.016574586 | V16: =S16/'Manufacturing inputs'!$B$5 -> 0.011944751 | W16: =T16/'Manufacturing inputs'!$B$5 -> 0.0048520833
A17: Tape casting machines | B17: Cells and glass sealants | C17: Big cell area | D17: 1 | E17: 507000 | F17: 50 | G17: 4.3 | H17: 2 | I17: 1 | J17: 7.5 | K17: {=IFERROR(INDEX(Max_cycle_table[Takt time], MATCH(1, (Max_cycle_table[Shifts/day]=I17) * (Max_cycle_table[Hours/shift]=J17), 0)),0)} -> 5.7 | L17: =IFERROR(IF(G17>K17,D17*ROUNDUP(G17/K17,0),D17),D17) -> 1 | M17: =IFERROR((G17/K17)*H17*L17*I17,0) -> 1.5087719 | N17: =VLOOKUP(C17,Scale_table[#All],2,FALSE) -> 1 | O17: =E17*L17*N17 -> 507000 | P17: =F17*L17*N17 -> 50 | Q17: =P17*G17 -> 215 | R17: =O17*'Manufacturing inputs'!$B$2 -> 20.28 | S17: =(M17*'Manufacturing inputs'!$B$9)/'Manufacturing inputs'!$B$1 -> 26.095719 | T17: =Q17*'Manufacturing inputs'!$B$8 -> 1.8376528 | U17: =R17/'Manufacturing inputs'!$B$5 -> 0.1120442 | V17: =S17/'Manufacturing inputs'!$B$5 -> 0.14417524 | W17: =T17/'Manufacturing inputs'!$B$5 -> 0.010152778
A18: PCB Loader | B18: Cells and glass sealants | C18: Length | D18: 2 | E18: 9091 | F18: =0.3/2 -> 0.15 | G18: 6.6 | H18: 0 | I18: 0 | K18: {=IFERROR(INDEX(Max_cycle_table[Takt time], MATCH(1, (Max_cycle_table[Shifts/day]=I18) * (Max_cycle_table[Hours/shift]=J18), 0)),0)} -> 0 | L18: =IFERROR(IF(G18>K18,D18*ROUNDUP(G18/K18,0),D18),D18) -> 2 | M18: =IFERROR((G18/K18)*H18*L18*I18,0) -> 0 | N18: =VLOOKUP(C18,Scale_table[#All],2,FALSE) -> 1 | O18: =E18*L18*N18 -> 18182 | P18: =F18*L18*N18 -> 0.3 | Q18: =P18*G18 -> 1.98 | R18: =O18*'Manufacturing inputs'!$B$2 -> 0.72728 | S18: =(M18*'Manufacturing inputs'!$B$9)/'Manufacturing inputs'!$B$1 -> 0 | T18: =Q18*'Manufacturing inputs'!$B$8 -> 0.0169235 | U18: =R18/'Manufacturing inputs'!$B$5 -> 0.0040181215 | V18: =S18/'Manufacturing inputs'!$B$5 -> 0 | W18: =T18/'Manufacturing inputs'!$B$5 -> 9.35e-05
A19: Screen printer (cells, glass sealant tape) | B19: Cells and glass sealants | C19: Frame | D19: 2 | E19: 68170 | F19: 1.5 | G19: 6.6 | H19: 1 | I19: 3 | J19: 7.5 | K19: {=IFERROR(INDEX(Max_cycle_table[Takt time], MATCH(1, (Max_cycle_table[Shifts/day]=I19) * (Max_cycle_table[Hours/shift]=J19), 0)),0)} -> 17.1 | L19: =IFERROR(IF(G19>K19,D19*ROUNDUP(G19/K19,0),D19),D19) -> 2 | M19: =IFERROR((G19/K19)*H19*L19*I19,0) -> 2.3157895 | N19: =VLOOKUP(C19,Scale_table[#All],2,FALSE) -> 0.9921095 | O19: =E19*L19*N19 -> 135264.21 | P19: =F19*L19*N19 -> 2.9763285 | Q19: =P19*G19 -> 19.643768 | R19: =O19*'Manufacturing inputs'!$B$2 -> 5.4105684 | S19: =(M19*'Manufacturing inputs'!$B$9)/'Manufacturing inputs'!$B$1 -> 40.053895 | T19: =Q19*'Manufacturing inputs'!$B$8 -> 0.16789965 | U19: =R19/'Manufacturing inputs'!$B$5 -> 0.029892643 | V19: =S19/'Manufacturing inputs'!$B$5 -> 0.22129224 | W19: =T19/'Manufacturing inputs'!$B$5 -> 0.00092762238
A20: Reflow oven | B20: Cells and glass sealants | C20: Big cell area | D20: 2 | E20: 42500 | F20: 22 | G20: 6.6 | H20: 0 | I20: 0 | K20: {=IFERROR(INDEX(Max_cycle_table[Takt time], MATCH(1, (Max_cycle_table[Shifts/day]=I20) * (Max_cycle_table[Hours/shift]=J20), 0)),0)} -> 0 | L20: =IFERROR(IF(G20>K20,D20*ROUNDUP(G20/K20,0),D20),D20) -> 2 | M20: =IFERROR((G20/K20)*H20*L20*I20,0) -> 0 | N20: =VLOOKUP(C20,Scale_table[#All],2,FALSE) -> 1 | O20: =E20*L20*N20 -> 85000 | P20: =F20*L20*N20 -> 44 | Q20: =P20*G20 -> 290.4 | R20: =O20*'Manufacturing inputs'!$B$2 -> 3.4 | S20: =(M20*'Manufacturing inputs'!$B$9)/'Manufacturing inputs'!$B$1 -> 0 | T20: =Q20*'Manufacturing inputs'!$B$8 -> 2.4821133 | U20: =R20/'Manufacturing inputs'!$B$5 -> 0.01878453 | V20: =S20/'Manufacturing inputs'!$B$5 -> 0 | W20: =T20/'Manufacturing inputs'!$B$5 -> 0.013713333
A21: PCB conveyer | B21: Cells and glass sealants | C21: Length | D21: 2 | E21: 3056 | F21: 0.1 | G21: 6.6 | H21: 0 | I21: 0 | K21: {=IFERROR(INDEX(Max_cycle_table[Takt time], MATCH(1, (Max_cycle_table[Shifts/day]=I21) * (Max_cycle_table[Hours/shift]=J21), 0)),0)} -> 0 | L21: =IFERROR(IF(G21>K21,D21*ROUNDUP(G21/K21,0),D21),D21) -> 2 | M21: =IFERROR((G21/K21)*H21*L21*I21,0) -> 0 | N21: =VLOOKUP(C21,Scale_table[#All],2,FALSE) -> 1 | O21: =E21*L21*N21 -> 6112 | P21: =F21*L21*N21 -> 0.2 | Q21: =P21*G21 -> 1.32 | R21: =O21*'Manufacturing inputs'!$B$2 -> 0.24448 | S21: =(M21*'Manufacturing inputs'!$B$9)/'Manufacturing inputs'!$B$1 -> 0 | T21: =Q21*'Manufacturing inputs'!$B$8 -> 0.011282333 | U21: =R21/'Manufacturing inputs'!$B$5 -> 0.0013507182 | V21: =S21/'Manufacturing inputs'!$B$5 -> 0 | W21: =T21/'Manufacturing inputs'!$B$5 -> 6.2333333e-05
A22: Tape cutter/slitter | B22: Cells and glass sealants | C22: Length | D22: 1 | E22: 15000 | F22: 1 | G22: 2 | H22: 1 | I22: 1 | J22: 7.5 | K22: {=IFERROR(INDEX(Max_cycle_table[Takt time], MATCH(1, (Max_cycle_table[Shifts/day]=I22) * (Max_cycle_table[Hours/shift]=J22), 0)),0)} -> 5.7 | L22: =IFERROR(IF(G22>K22,D22*ROUNDUP(G22/K22,0),D22),D22) -> 1 | M22: =IFERROR((G22/K22)*H22*L22*I22,0) -> 0.35087719 | N22: =VLOOKUP(C22,Scale_table[#All],2,FALSE) -> 1 | O22: =E22*L22*N22 -> 15000 | P22: =F22*L22*N22 -> 1 | Q22: =P22*G22 -> 2 | R22: =O22*'Manufacturing inputs'!$B$2 -> 0.6 | S22: =(M22*'Manufacturing inputs'!$B$9)/'Manufacturing inputs'!$B$1 -> 6.0687719 | T22: =Q22*'Manufacturing inputs'!$B$8 -> 0.017094444 | U22: =R22/'Manufacturing inputs'!$B$5 -> 0.0033149171 | V22: =S22/'Manufacturing inputs'!$B$5 -> 0.033529127 | W22: =T22/'Manufacturing inputs'!$B$5 -> 9.4444444e-05
A23: Firing kiln (3-shift) | B23: Cells and glass sealants | C23: Big cell area | D23: 1 | E23: 2550000 | F23: 320 | G23: 18.3 | H23: 0.5 | I23: 3 | J23: 8 | K23: {=IFERROR(INDEX(Max_cycle_table[Takt time], MATCH(1, (Max_cycle_table[Shifts/day]=I23) * (Max_cycle_table[Hours/shift]=J23), 0)),0)} -> 18.3 | L23: =IFERROR(IF(G23>K23,D23*ROUNDUP(G23/K23,0),D23),D23) -> 1 | M23: =IFERROR((G23/K23)*H23*L23*I23,0) -> 1.5 | N23: =VLOOKUP(C23,Scale_table[#All],2,FALSE) -> 1 | O23: =E23*L23*N23 -> 2550000 | P23: =F23*L23*N23 -> 320 | Q23: =P23*G23 -> 5856 | R23: =O23*'Manufacturing inputs'!$B$2 -> 102 | S23: =(M23*'Manufacturing inputs'!$B$9)/'Manufacturing inputs'!$B$1 -> 25.944 | T23: =Q23*'Manufacturing inputs'!$B$8 -> 50.052533 | U23: =R23/'Manufacturing inputs'!$B$5 -> 0.56353591 | V23: =S23/'Manufacturing inputs'!$B$5 -> 0.14333702 | W23: =T23/'Manufacturing inputs'!$B$5 -> 0.27653333
A24: Machinery for sealent slurry preparation | B24: Cells and glass sealants | C24: Big cell area | D24: 1 | E24: 46875 | F24: 5.5 | G24: 11 | L24: =IFERROR(IF(G24>K24,D24*ROUNDUP(G24/K24,0),D24),D24) -> 1 | M24: =1/7.5*L24 -> 0.13333333 | N24: =VLOOKUP(C24,Scale_table[#All],2,FALSE) -> 1 | O24: =E24*L24*N24 -> 46875 | P24: =F24*L24*N24 -> 5.5 | Q24: =P24*G24 -> 60.5 | R24: =O24*'Manufacturing inputs'!$B$2 -> 1.875 | S24: =(M24*'Manufacturing inputs'!$B$9)/'Manufacturing inputs'!$B$1 -> 2.3061333 | T24: =Q24*'Manufacturing inputs'!$B$8 -> 0.51710694 | U24: =R24/'Manufacturing inputs'!$B$5 -> 0.010359116 | V24: =S24/'Manufacturing inputs'!$B$5 -> 0.012741068 | W24: =T24/'Manufacturing inputs'!$B$5 -> 0.0028569444
A25: Laser welder | B25: Pre-assembly | C25: Length | D25: 2 | E25: =340000/2 -> 170000 | F25: 5 | G25: 16.2 | H25: 0.2 | I25: 3 | J25: 7.5 | K25: {=IFERROR(INDEX(Max_cycle_table[Takt time], MATCH(1, (Max_cycle_table[Shifts/day]=I25) * (Max_cycle_table[Hours/shift]=J25), 0)),0)} -> 17.1 | L25: =IFERROR(IF(G25>K25,D25*ROUNDUP(G25/K25,0),D25),D25) -> 2 | M25: =IFERROR((G25/K25)*H25*L25*I25,0) -> 1.1368421 | N25: =VLOOKUP(C25,Scale_table[#All],2,FALSE) -> 1 | O25: =E25*L25*N25 -> 340000 | P25: =F25*L25*N25 -> 10 | Q25: =P25*G25 -> 162 | R25: =O25*'Manufacturing inputs'!$B$2 -> 13.6 | S25: =(M25*'Manufacturing inputs'!$B$9)/'Manufacturing inputs'!$B$1 -> 19.662821 | T25: =Q25*'Manufacturing inputs'!$B$8 -> 1.38465 | U25: =R25/'Manufacturing inputs'!$B$5 -> 0.075138122 | V25: =S25/'Manufacturing inputs'!$B$5 -> 0.10863437 | W25: =T25/'Manufacturing inputs'!$B$5 -> 0.00765
A26: Robot assembly stations | B26: Pre-assembly | C26: Frame | D26: 8 | E26: =720000/8 -> 90000 | F26: 2 | G26: 5.1 | H26: 0.2 | I26: 1 | J26: 7.5 | K26: {=IFERROR(INDEX(Max_cycle_table[Takt time], MATCH(1, (Max_cycle_table[Shifts/day]=I26) * (Max_cycle_table[Hours/shift]=J26), 0)),0)} -> 5.7 | L26: 8 | M26: =IFERROR((G26/K26)*H26*L26*I26,0) -> 1.4315789 | N26: =VLOOKUP(C26,Scale_table[#All],2,FALSE) -> 0.9921095 | O26: =E26*L26*N26 -> 714318.84 | P26: =F26*L26*N26 -> 15.873752 | Q26: =P26*G26 -> 80.956135 | R26: =O26*'Manufacturing inputs'!$B$2 -> 28.572754 | S26: =(M26*'Manufacturing inputs'!$B$9)/'Manufacturing inputs'!$B$1 -> 24.760589 | T26: =Q26*'Manufacturing inputs'!$B$8 -> 0.69195008 | U26: =R26/'Manufacturing inputs'!$B$5 -> 0.15786052 | V26: =S26/'Manufacturing inputs'!$B$5 -> 0.13679884 | W26: =T26/'Manufacturing inputs'!$B$5 -> 0.0038229286
A27: Annealing oven | B27: Pre-assembly | C27: Frame | D27: 1 | E27: 1147500 | F27: 100 | G27: 17.6 | H27: 0.2 | I27: 3 | J27: 8 | K27: {=IFERROR(INDEX(Max_cycle_table[Takt time], MATCH(1, (Max_cycle_table[Shifts/day]=I27) * (Max_cycle_table[Hours/shift]=J27), 0)),0)} -> 18.3 | L27: =IFERROR(IF(G27>K27,D27*ROUNDUP(G27/K27,0),D27),D27) -> 1 | M27: =IFERROR((G27/K27)*H27*L27*I27,0) -> 0.57704918 | N27: =VLOOKUP(C27,Scale_table[#All],2,FALSE) -> 0.9921095 | O27: =E27*L27*N27 -> 1138445.7 | P27: =F27*L27*N27 -> 99.21095 | Q27: =P27*G27 -> 1746.1127 | R27: =O27*'Manufacturing inputs'!$B$2 -> 45.537826 | S27: =(M27*'Manufacturing inputs'!$B$9)/'Manufacturing inputs'!$B$1 -> 9.9806426 | T27: =Q27*'Manufacturing inputs'!$B$8 -> 14.924413 | U27: =R27/'Manufacturing inputs'!$B$5 -> 0.2515902 | V27: =S27/'Manufacturing inputs'!$B$5 -> 0.055141672 | W27: =T27/'Manufacturing inputs'!$B$5 -> 0.082455323
A28: Assembly line | B28: Final assembly | C28: Frame | D28: 1 | E28: 80000 | F28: 0 | G28: 0 | H28: 1.6 | I28: 0 | K28: {=IFERROR(INDEX(Max_cycle_table[Takt time], MATCH(1, (Max_cycle_table[Shifts/day]=I28) * (Max_cycle_table[Hours/shift]=J28), 0)),0)} -> 0 | L28: =IFERROR(IF(G28>K28,D28*ROUNDUP(G28/K28,0),D28),D28) -> 1 | M28: =H28*L28 -> 1.6 | N28: =VLOOKUP(C28,Scale_table[#All],2,FALSE) -> 0.9921095 | O28: =E28*L28*N28 -> 79368.76 | P28: =F28*L28*N28 -> 0 | Q28: =P28*G28 -> 0 | R28: =O28*'Manufacturing inputs'!$B$2 -> 3.1747504 | S28: =(M28*'Manufacturing inputs'!$B$9)/'Manufacturing inputs'!$B$1 -> 27.6736 | T28: =Q28*'Manufacturing inputs'!$B$8 -> 0 | U28: =R28/'Manufacturing inputs'!$B$5 -> 0.017540057 | V28: =S28/'Manufacturing inputs'!$B$5 -> 0.15289282 | W28: =T28/'Manufacturing inputs'!$B$5 -> 0
A29: Sintering and testing line | B29: Final assembly | C29: Frame | D29: 1 | E29: 1700000 | F29: 90 | G29: 1 | H29: 2 | I29: 0 | K29: {=IFERROR(INDEX(Max_cycle_table[Takt time], MATCH(1, (Max_cycle_table[Shifts/day]=I29) * (Max_cycle_table[Hours/shift]=J29), 0)),0)} -> 0 | L29: =IFERROR(IF(G29>K29,D29*ROUNDUP(G29/K29,0),D29),D29) -> 1 | M29: =H29*G29*L29 -> 2 | N29: =VLOOKUP(C29,Scale_table[#All],2,FALSE) -> 0.9921095 | O29: =E29*L29*N29 -> 1686586.2 | P29: =F29*L29*N29 -> 89.289855 | Q29: =P29*G29*24/24.5 -> 87.467613 | R29: =O29*'Manufacturing inputs'!$B$2 -> 67.463446 | S29: =(M29*'Manufacturing inputs'!$B$9)/'Manufacturing inputs'!$B$1 -> 34.592 | T29: =Q29 -> 87.467613 | U29: =R29/'Manufacturing inputs'!$B$5 -> 0.37272622 | V29: =S29/'Manufacturing inputs'!$B$5 -> 0.19111602 | W29: =T29/'Manufacturing inputs'!$B$5 -> 0.48324648

Sheet Materials
B1: [€/kg] | C1: [g/cm^3] | I1: [€/m^2]
A2: Material | B2: Cost | C2: Density | H2: Ni-Mesh | I2: 27
A3: SS441 | B3: 1.7 | C3: 7.8
A4: 8YSZ | B4: 30 | C4: 6.3
A5: ScYSZ | B5: 30 | C5: 6.1
A6: CGO | B6: 260 | C6: 7.23
A7: LSC | B7: 55 | C7: 6.3
A8: Crofer22APU | B8: 25 | C8: 7.8
A9: Crofer22H | B9: 19 | C9: 7.8
A10: NiO | B10: 29 | C10: 6.67
A11: LSCF | B11: =B7 -> 55 | C11: =C7 -> 6.3
A12: LSFNT | B12: =B7 -> 55 | C12: =C7 -> 6.3
A13: Ni/CGO | B13: =B6 -> 260 | C13: =C6 -> 7.23

Sheet Calculations
A1: This sheet is used to estimate the fraction of each metal component, which needs to be cut out in order for other components to fit in
A3: Below are the 2-dimensional measurements for the reference design:
A5: Cell length: | B5: ='Cross-layer'!B4+'Cross-layer'!B6 -> 17 | C5: cm
A6: Cell width: | B6: ='Cross-layer'!B5+'Cross-layer'!B6 -> 9 | C6: cm
A7: Cell ratio | B7: ='Cross-layer'!B6 -> 1
A8: Frame constant | B8: ='Cross-layer'!B7 -> 3.2 | C8: cm
A10: Meaning the total frame is:
A12: Frame length: | B12: ='Cross-layer'!B22 -> 20.2 | C12: cm
A13: Frame width: | B13: ='Cross-layer'!B23 -> 12.2 | C13: cm
A15: All metal layers contain holes for gas flow, which need to be included
A17: Retry:
A19: Fuel hole radius base | B19: =0.4/2 -> 0.2 | C19: cm
A20: Fuel hole area base | B20: =PI()*B19^2 -> 0.12566371 | C20: cm^2
A21: Frame constant base: | B21: 1.2 | C21: cm
A22: Scaler: | B22: =B8/B21 -> 2.6666667
A23: Actual area | B23: =B20*B22 -> 0.33510322 | C23: cm^2
A24: Actual radius | B24: =SQRT(B23/PI()) -> 0.32659863 | C24: cm
A26: Base number of holes | B26: 14
A27: Cell length base | B27: 11 | C27: cm
A28: Scaler | B28: =B5/B27 -> 1.5454545
A29: New nr. of holes | B29: =INT(B26*B28) -> 21
A32: A_holes: | B32: =B23*B29*2 -> 14.074335 | C32: cm^2
A34: Frame area with metal: | B34: =B12*B13-B32 -> 232.36566 | C34: cm^2
A35: % of frame area: | B35: =B34/(B13*B12) -> 0.9428894
A37: Assumption: | B37: Both spacer-layers and interconnect layers have holes cut out for the cell.
A39: Frame area: | B39: =B12*B13 -> 246.44 | C39: cm^2
A40: Cell area: | B40: =B6*B5 -> 153 | C40: cm^2
A42: Metal area: | B42: =B39-B40-B32 -> 79.365665 | C42: cm^2 | D42: (for spacers and IC)
A43: %of frame: | B43: =B42/B39 -> 0.32204863
A45: Harboe stack design: | B45: To reverse-engineer the glass sealant use and density:
A47: Cell area | B47: 128 | C47: cm^2
A48: Cells per stack | B48: 60
A49: Stacks per 5kW | B49: 3.02
A50: Total cells per 5kW | B50: =B49*B48 -> 181.2
A51: Total glass sealant | B51: 2.2 | C51: kg
A52: Glass sealant per cell | B52: =B51/B50 -> 0.01214128 | C52: kg
B53: =B52*1000 -> 12.14128 | C53: g
A55: Total sealant height | B55: 700 | C55: [µm] | D55: (from source:) | F55: https://juser.fz-juelich.de/record/842212/files/Energie_Umwelt_391.pdf
A57: Dimensions:
A58: Length | B58: 180 | C58: mm
...
